Workbook

Sheet PLAYER_STATS
A1: 닉네임 | B1: 경기 수 | C1: 승 | D1: 패 | E1: 승률 | F1: 평균 KDA | G1: TOP 승률 | H1: JG 승률 | I1: MID 승률 | J1: ADC 승률 | K1: SUP 승률 | L1: 모스트 1 | N1: 모스트 2 | P1: 모스트 3 | R1: K | S1: D | T1: A
A2: 동욱 | B2: =COUNTIF(MATCH_LOG!A:A,A2) -> 42 | C2: =COUNTIFS(MATCH_LOG!A:A,A2,MATCH_LOG!G:G,"승") -> 24 | D2: =COUNTIFS(MATCH_LOG!A:A,A2,MATCH_LOG!G:G,"패") -> 18 | E2: =IF(B2=0,0,C2/B2) -> 0.57142857 | F2: =IFERROR((SUMIFS(MATCH_LOG!D:D,MATCH_LOG!A:A,A2)+SUMIFS(MATCH_LOG!F:F,MATCH_LOG!A:A,A2))/SUMIFS(MATCH_LOG!E:E,MATCH_LOG!A:A,A2),0) -> 3.3681818 | G2: =IFERROR(COUNTIFS(MATCH_LOG!A:A,A2,MATCH_LOG!B:B,"TOP",MATCH_LOG!G:G,"승")/COUNTIFS(MATCH_LOG!A:A,A2,MATCH_LOG!B:B,"TOP"),0) -> 0.78571429 | H2: =IFERROR(COUNTIFS(MATCH_LOG!A:A,A2,MATCH_LOG!B:B,"JG",MATCH_LOG!G:G,"승")/COUNTIFS(MATCH_LOG!A:A,A2,MATCH_LOG!B:B,"JG"),0) -> 0.53333333 | I2: =IFERROR(COUNTIFS(MATCH_LOG!A:A,A2,MATCH_LOG!B:B,"MID",MATCH_LOG!G:G,"승")/COUNTIFS(MATCH_LOG!A:A,A2,MATCH_LOG!B:B,"MID"),0) -> 0.5 | J2: =IFERROR(COUNTIFS(MATCH_LOG!A:A,A2,MATCH_LOG!B:B,"ADC",MATCH_LOG!G:G,"승")/COUNTIFS(MATCH_LOG!A:A,A2,MATCH_LOG!B:B,"ADC"),0) -> 0 | K2: =IFERROR(COUNTIFS(MATCH_LOG!A:A,A2,MATCH_LOG!B:B,"SUP",MATCH_LOG!G:G,"승")/COUNTIFS(MATCH_LOG!A:A,A2,MATCH_LOG!B:B,"SUP"),0) -> 0.4 | L2: 리신 | M2: 5 | N2: 레넥톤 | O2: 5 | P2: 나피리 | Q2: 4 | R2: =SUMIFS(MATCH_LOG!D:D,MATCH_LOG!A:A,A2) -> 368 | S2: =SUMIFS(MATCH_LOG!E:E,MATCH_LOG!A:A,A2) -> 220 | T2: =SUMIFS(MATCH_LOG!F:F,MATCH_LOG!A:A,A2) -> 373
A3: 희영 | B3: =COUNTIF(MATCH_LOG!A:A,A3) -> 27 | C3: =COUNTIFS(MATCH_LOG!A:A,A3,MATCH_LOG!G:G,"승") -> 15 | D3: =COUNTIFS(MATCH_LOG!A:A,A3,MATCH_LOG!G:G,"패") -> 12 | E3: =IF(B3=0,0,C3/B3) -> 0.55555556 | F3: =IFERROR((SUMIFS(MATCH_LOG!D:D,MATCH_LOG!A:A,A3)+SUMIFS(MATCH_LOG!F:F,MATCH_LOG!A:A,A3))/SUMIFS(MATCH_LOG!E:E,MATCH_LOG!A:A,A3),0) -> 3.5403226 | G3: =IFERROR(COUNTIFS(MATCH_LOG!A:A,A3,MATCH_LOG!B:B,"TOP",MATCH_LOG!G:G,"승")/COUNTIFS(MATCH_LOG!A:A,A3,MATCH_LOG!B:B,"TOP"),0) -> 0.66666667 | H3: =IFERROR(COUNTIFS(MATCH_LOG!A:A,A3,MATCH_LOG!B:B,"JG",MATCH_LOG!G:G,"승")/COUNTIFS(MATCH_LOG!A:A,A3,MATCH_LOG!B:B,"JG"),0) -> 0.5625 | I3: =IFERROR(COUNTIFS(MATCH_LOG!A:A,A3,MATCH_LOG!B:B,"MID",MATCH_LOG!G:G,"승")/COUNTIFS(MATCH_LOG!A:A,A3,MATCH_LOG!B:B,"MID"),0) -> 0.66666667 | J3: =IFERROR(COUNTIFS(MATCH_LOG!A:A,A3,MATCH_LOG!B:B,"ADC",MATCH_LOG!G:G,"승")/COUNTIFS(MATCH_LOG!A:A,A3,MATCH_LOG!B:B,"ADC"),0) -> 0 | K3: =IFERROR(COUNTIFS(MATCH_LOG!A:A,A3,MATCH_LOG!B:B,"SUP",MATCH_LOG!G:G,"승")/COUNTIFS(MATCH_LOG!A:A,A3,MATCH_LOG!B:B,"SUP"),0) -> 0 | L3: 자헨 | M3: 5 | N3: 바이 | O3: 2 | P3: 스카너 | Q3: 2 | R3: =SUMIFS(MATCH_LOG!D:D,MATCH_LOG!A:A,A3) -> 195 | S3: =SUMIFS(MATCH_LOG!E:E,MATCH_LOG!A:A,A3) -> 124 | T3: =SUMIFS(MATCH_LOG!F:F,MATCH_LOG!A:A,A3) -> 244
A4: 도현 | B4: =COUNTIF(MATCH_LOG!A:A,A4) -> 36 | C4: =COUNTIFS(MATCH_LOG!A:A,A4,MATCH_LOG!G:G,"승") -> 16 | D4: =COUNTIFS(MATCH_LOG!A:A,A4,MATCH_LOG!G:G,"패") -> 20 | E4: =IF(B4=0,0,C4/B4) -> 0.44444444 | F4: =IFERROR((SUMIFS(MATCH_LOG!D:D,MATCH_LOG!A:A,A4)+SUMIFS(MATCH_LOG!F:F,MATCH_LOG!A:A,A4))/SUMIFS(MATCH_LOG!E:E,MATCH_LOG!A:A,A4),0) -> 1.9959184 | G4: =IFERROR(COUNTIFS(MATCH_LOG!A:A,A4,MATCH_LOG!B:B,"TOP",MATCH_LOG!G:G,"승")/COUNTIFS(MATCH_LOG!A:A,A4,MATCH_LOG!B:B,"TOP"),0) -> 0.16666667 | H4: =IFERROR(COUNTIFS(MATCH_LOG!A:A,A4,MATCH_LOG!B:B,"JG",MATCH_LOG!G:G,"승")/COUNTIFS(MATCH_LOG!A:A,A4,MATCH_LOG!B:B,"JG"),0) -> 0 | I4: =IFERROR(COUNTIFS(MATCH_LOG!A:A,A4,MATCH_LOG!B:B,"MID",MATCH_LOG!G:G,"승")/COUNTIFS(MATCH_LOG!A:A,A4,MATCH_LOG!B:B,"MID"),0) -> 0.5 | J4: =IFERROR(COUNTIFS(MATCH_LOG!A:A,A4,MATCH_LOG!B:B,"ADC",MATCH_LOG!G:G,"승")/COUNTIFS(MATCH_LOG!A:A,A4,MATCH_LOG!B:B,"ADC"),0) -> 0 | K4: =IFERROR(COUNTIFS(MATCH_LOG!A:A,A4,MATCH_LOG!B:B,"SUP",MATCH_LOG!G:G,"승")/COUNTIFS(MATCH_LOG!A:A,A4,MATCH_LOG!B:B,"SUP"),0) -> 0 | L4: 요네 | M4: 7 | N4: 사일러스 | O4: 7 | P4: 야스오 | Q4: 3 | R4: =SUMIFS(MATCH_LOG!D:D,MATCH_LOG!A:A,A4) -> 262 | S4: =SUMIFS(MATCH_LOG!E:E,MATCH_LOG!A:A,A4) -> 245 | T4: =SUMIFS(MATCH_LOG!F:F,MATCH_LOG!A:A,A4) -> 227
A5: 영훈 | B5: =COUNTIF(MATCH_LOG!A:A,A5) -> 5 | C5: =COUNTIFS(MATCH_LOG!A:A,A5,MATCH_LOG!G:G,"승") -> 3 | D5: =COUNTIFS(MATCH_LOG!A:A,A5,MATCH_LOG!G:G,"패") -> 2 | E5: =IF(B5=0,0,C5/B5) -> 0.6 | F5: =IFERROR((SUMIFS(MATCH_LOG!D:D,MATCH_LOG!A:A,A5)+SUMIFS(MATCH_LOG!F:F,MATCH_LOG!A:A,A5))/SUMIFS(MATCH_LOG!E:E,MATCH_LOG!A:A,A5),0) -> 2.5294118 | G5: =IFERROR(COUNTIFS(MATCH_LOG!A:A,A5,MATCH_LOG!B:B,"TOP",MATCH_LOG!G:G,"승")/COUNTIFS(MATCH_LOG!A:A,A5,MATCH_LOG!B:B,"TOP"),0) -> 0 | H5: =IFERROR(COUNTIFS(MATCH_LOG!A:A,A5,MATCH_LOG!B:B,"JG",MATCH_LOG!G:G,"승")/COUNTIFS(MATCH_LOG!A:A,A5,MATCH_LOG!B:B,"JG"),0) -> 0 | I5: =IFERROR(COUNTIFS(MATCH_LOG!A:A,A5,MATCH_LOG!B:B,"MID",MATCH_LOG!G:G,"승")/COUNTIFS(MATCH_LOG!A:A,A5,MATCH_LOG!B:B,"MID"),0) -> 1 | J5: =IFERROR(COUNTIFS(MATCH_LOG!A:A,A5,MATCH_LOG!B:B,"ADC",MATCH_LOG!G:G,"승")/COUNTIFS(MATCH_LOG!A:A,A5,MATCH_LOG!B:B,"ADC"),0) -> 0.5 | K5: =IFERROR(COUNTIFS(MATCH_LOG!A:A,A5,MATCH_LOG!B:B,"SUP",MATCH_LOG!G:G,"승")/COUNTIFS(MATCH_LOG!A:A,A5,MATCH_LOG!B:B,"SUP"),0) -> 0 | L5: 케이틀린 | M5: 2 | N5: 루시안 | O5: 1 | P5: 아지르 | Q5: 1 | R5: =SUMIFS(MATCH_LOG!D:D,MATCH_LOG!A:A,A5) -> 48 | S5: =SUMIFS(MATCH_LOG!E:E,MATCH_LOG!A:A,A5) -> 34 | T5: =SUMIFS(MATCH_LOG!F:F,MATCH_LOG!A:A,A5) -> 38
A6: 스마 | B6: =COUNTIF(MATCH_LOG!A:A,A6) -> 24 | C6: =COUNTIFS(MATCH_LOG!A:A,A6,MATCH_LOG!G:G,"승") -> 12 | D6: =COUNTIFS(MATCH_LOG!A:A,A6,MATCH_LOG!G:G,"패") -> 12 | E6: =IF(B6=0,0,C6/B6) -> 0.5 | F6: =IFERROR((SUMIFS(MATCH_LOG!D:D,MATCH_LOG!A:A,A6)+SUMIFS(MATCH_LOG!F:F,MATCH_LOG!A:A,A6))/SUMIFS(MATCH_LOG!E:E,MATCH_LOG!A:A,A6),0) -> 2.9562044 | G6: =IFERROR(COUNTIFS(MATCH_LOG!A:A,A6,MATCH_LOG!B:B,"TOP",MATCH_LOG!G:G,"승")/COUNTIFS(MATCH_LOG!A:A,A6,MATCH_LOG!B:B,"TOP"),0) -> 0 | H6: =IFERROR(COUNTIFS(MATCH_LOG!A:A,A6,MATCH_LOG!B:B,"JG",MATCH_LOG!G:G,"승")/COUNTIFS(MATCH_LOG!A:A,A6,MATCH_LOG!B:B,"JG"),0) -> 0.75 | I6: =IFERROR(COUNTIFS(MATCH_LOG!A:A,A6,MATCH_LOG!B:B,"MID",MATCH_LOG!G:G,"승")/COUNTIFS(MATCH_LOG!A:A,A6,MATCH_LOG!B:B,"MID"),0) -> 0 | J6: =IFERROR(COUNTIFS(MATCH_LOG!A:A,A6,MATCH_LOG!B:B,"ADC",MATCH_LOG!G:G,"승")/COUNTIFS(MATCH_LOG!A:A,A6,MATCH_LOG!B:B,"ADC"),0) -> 0.25 | K6: =IFERROR(COUNTIFS(MATCH_LOG!A:A,A6,MATCH_LOG!B:B,"SUP",MATCH_LOG!G:G,"승")/COUNTIFS(MATCH_LOG!A:A,A6,MATCH_LOG!B:B,"SUP"),0) -> 0.57142857 | L6: 트위치 | M6: 3 | N6: 바드 | O6: 2 | P6: 루시안 | Q6: 2 | R6: =SUMIFS(MATCH_LOG!D:D,MATCH_LOG!A:A,A6) -> 135 | S6: =SUMIFS(MATCH_LOG!E:E,MATCH_LOG!A:A,A6) -> 137 | T6: =SUMIFS(MATCH_LOG!F:F,MATCH_LOG!A:A,A6) -> 270
A7: 수호 | B7: =COUNTIF(MATCH_LOG!A:A,A7) -> 14 | C7: =COUNTIFS(MATCH_LOG!A:A,A7,MATCH_LOG!G:G,"승") -> 5 | D7: =COUNTIFS(MATCH_LOG!A:A,A7,MATCH_LOG!G:G,"패") -> 9 | E7: =IF(B7=0,0,C7/B7) -> 0.35714286 | F7: =IFERROR((SUMIFS(MATCH_LOG!D:D,MATCH_LOG!A:A,A7)+SUMIFS(MATCH_LOG!F:F,MATCH_LOG!A:A,A7))/SUMIFS(MATCH_LOG!E:E,MATCH_LOG!A:A,A7),0) -> 1.7747748 | G7: =IFERROR(COUNTIFS(MATCH_LOG!A:A,A7,MATCH_LOG!B:B,"TOP",MATCH_LOG!G:G,"승")/COUNTIFS(MATCH_LOG!A:A,A7,MATCH_LOG!B:B,"TOP"),0) -> 0.33333333 | H7: =IFERROR(COUNTIFS(MATCH_LOG!A:A,A7,MATCH_LOG!B:B,"JG",MATCH_LOG!G:G,"승")/COUNTIFS(MATCH_LOG!A:A,A7,MATCH_LOG!B:B,"JG"),0) -> 0.5 | I7: =IFERROR(COUNTIFS(MATCH_LOG!A:A,A7,MATCH_LOG!B:B,"MID",MATCH_LOG!G:G,"승")/COUNTIFS(MATCH_LOG!A:A,A7,MATCH_LOG!B:B,"MID"),0) -> 0.33333333 | J7: =IFERROR(COUNTIFS(MATCH_LOG!A:A,A7,MATCH_LOG!B:B,"ADC",MATCH_LOG!G:G,"승")/COUNTIFS(MATCH_LOG!A:A,A7,MATCH_LOG!B:B,"ADC"),0) -> 0 | K7: =IFERROR(COUNTIFS(MATCH_LOG!A:A,A7,MATCH_LOG!B:B,"SUP",MATCH_LOG!G:G,"승")/COUNTIFS(MATCH_LOG!A:A,A7,MATCH_LOG!B:B,"SUP"),0) -> 0 | L7: 오공 | M7: 2 | N7: 비에고 | O7: 1 | P7: 자르반 | Q7: 1 | R7: =SUMIFS(MATCH_LOG!D:D,MATCH_LOG!A:A,A7) -> 130 | S7: =SUMIFS(MATCH_LOG!E:E,MATCH_LOG!A:A,A7) -> 111 | T7: =SUMIFS(MATCH_LOG!F:F,MATCH_LOG!A:A,A7) -> 67
A8: 블루 | B8: =COUNTIF(MATCH_LOG!A:A,A8) -> 22 | C8: =COUNTIFS(MATCH_LOG!A:A,A8,MATCH_LOG!G:G,"승") -> 9 | D8: =COUNTIFS(MATCH_LOG!A:A,A8,MATCH_LOG!G:G,"패") -> 13 | E8: =IF(B8=0,0,C8/B8) -> 0.40909091 | F8: =IFERROR((SUMIFS(MATCH_LOG!D:D,MATCH_LOG!A:A,A8)+SUMIFS(MATCH_LOG!F:F,MATCH_LOG!A:A,A8))/SUMIFS(MATCH_LOG!E:E,MATCH_LOG!A:A,A8),0) -> 2.381295 | G8: =IFERROR(COUNTIFS(MATCH_LOG!A:A,A8,MATCH_LOG!B:B,"TOP",MATCH_LOG!G:G,"승")/COUNTIFS(MATCH_LOG!A:A,A8,MATCH_LOG!B:B,"TOP"),0) -> 0.5 | H8: =IFERROR(COUNTIFS(MATCH_LOG!A:A,A8,MATCH_LOG!B:B,"JG",MATCH_LOG!G:G,"승")/COUNTIFS(MATCH_LOG!A:A,A8,MATCH_LOG!B:B,"JG"),0) -> 0 | I8: =IFERROR(COUNTIFS(MATCH_LOG!A:A,A8,MATCH_LOG!B:B,"MID",MATCH_LOG!G:G,"승")/COUNTIFS(MATCH_LOG!A:A,A8,MATCH_LOG!B:B,"MID"),0) -> 0.44444444 | J8: =IFERROR(COUNTIFS(MATCH_LOG!A:A,A8,MATCH_LOG!B:B,"ADC",MATCH_LOG!G:G,"승")/COUNTIFS(MATCH_LOG!A:A,A8,MATCH_LOG!B:B,"ADC"),0) -> 0 | K8: =IFERROR(COUNTIFS(MATCH_LOG!A:A,A8,MATCH_LOG!B:B,"SUP",MATCH_LOG!G:G,"승")/COUNTIFS(MATCH_LOG!A:A,A8,MATCH_LOG!B:B,"SUP"),0) -> 0 | L8: 아칼리 | M8: 4 | N8: 갈리오 | O8: 2 | P8: 카시오페아 | Q8: 2 | R8: =SUMIFS(MATCH_LOG!D:D,MATCH_LOG!A:A,A8) -> 161 | S8: =SUMIFS(MATCH_LOG!E:E,MATCH_LOG!A:A,A8) -> 139 | T8: =SUMIFS(MATCH_LOG!F:F,MATCH_LOG!A:A,A8) -> 170
A9: 네잉 | B9: =COUNTIF(MATCH_LOG!A:A,A9) -> 5 | C9: =COUNTIFS(MATCH_LOG!A:A,A9,MATCH_LOG!G:G,"승") -> 5 | D9: =COUNTIFS(MATCH_LOG!A:A,A9,MATCH_LOG!G:G,"패") -> 0 | E9: =IF(B9=0,0,C9/B9) -> 1 | F9: =IFERROR((SUMIFS(MATCH_LOG!D:D,MATCH_LOG!A:A,A9)+SUMIFS(MATCH_LOG!F:F,MATCH_LOG!A:A,A9))/SUMIFS(MATCH_LOG!E:E,MATCH_LOG!A:A,A9),0) -> 2.483871 | G9: =IFERROR(COUNTIFS(MATCH_LOG!A:A,A9,MATCH_LOG!B:B,"TOP",MATCH_LOG!G:G,"승")/COUNTIFS(MATCH_LOG!A:A,A9,MATCH_LOG!B:B,"TOP"),0) -> 0 | H9: =IFERROR(COUNTIFS(MATCH_LOG!A:A,A9,MATCH_LOG!B:B,"JG",MATCH_LOG!G:G,"승")/COUNTIFS(MATCH_LOG!A:A,A9,MATCH_LOG!B:B,"JG"),0) -> 0 | I9: =IFERROR(COUNTIFS(MATCH_LOG!A:A,A9,MATCH_LOG!B:B,"MID",MATCH_LOG!G:G,"승")/COUNTIFS(MATCH_LOG!A:A,A9,MATCH_LOG!B:B,"MID"),0) -> 0 | J9: =IFERROR(COUNTIFS(MATCH_LOG!A:A,A9,MATCH_LOG!B:B,"ADC",MATCH_LOG!G:G,"승")/COUNTIFS(MATCH_LOG!A:A,A9,MATCH_LOG!B:B,"ADC"),0) -> 1 | K9: =IFERROR(COUNTIFS(MATCH_LOG!A:A,A9,MATCH_LOG!B:B,"SUP",MATCH_LOG!G:G,"승")/COUNTIFS(MATCH_LOG!A:A,A9,MATCH_LOG!B:B,"SUP"),0) -> 0 | L9: 이즈리얼 | M9: 2 | N9: 루시안 | O9: 1 | P9: 케이틀린 | Q9: 1 | R9: =SUMIFS(MATCH_LOG!D:D,MATCH_LOG!A:A,A9) -> 40 | S9: =SUMIFS(MATCH_LOG!E:E,MATCH_LOG!A:A,A9) -> 31 | T9: =SUMIFS(MATCH_LOG!F:F,MATCH_LOG!A:A,A9) -> 37
A10: 센도 | B10: =COUNTIF(MATCH_LOG!A:A,A10) -> 9 | C10: =COUNTIFS(MATCH_LOG!A:A,A10,MATCH_LOG!G:G,"승") -> 3 | D10: =COUNTIFS(MATCH_LOG!A:A,A10,MATCH_LOG!G:G,"패") -> 6 | E10: =IF(B10=0,0,C10/B10) -> 0.33333333 | F10: =IFERROR((SUMIFS(MATCH_LOG!D:D,MATCH_LOG!A:A,A10)+SUMIFS(MATCH_LOG!F:F,MATCH_LOG!A:A,A10))/SUMIFS(MATCH_LOG!E:E,MATCH_LOG!A:A,A10),0) -> 2.7346939 | G10: =IFERROR(COUNTIFS(MATCH_LOG!A:A,A10,MATCH_LOG!B:B,"TOP",MATCH_LOG!G:G,"승")/COUNTIFS(MATCH_LOG!A:A,A10,MATCH_LOG!B:B,"TOP"),0) -> 0 | H10: =IFERROR(COUNTIFS(MATCH_LOG!A:A,A10,MATCH_LOG!B:B,"JG",MATCH_LOG!G:G,"승")/COUNTIFS(MATCH_LOG!A:A,A10,MATCH_LOG!B:B,"JG"),0) -> 0 | I10: =IFERROR(COUNTIFS(MATCH_LOG!A:A,A10,MATCH_LOG!B:B,"MID",MATCH_LOG!G:G,"승")/COUNTIFS(MATCH_LOG!A:A,A10,MATCH_LOG!B:B,"MID"),0) -> 0.28571429 | J10: =IFERROR(COUNTIFS(MATCH_LOG!A:A,A10,MATCH_LOG!B:B,"ADC",MATCH_LOG!G:G,"승")/COUNTIFS(MATCH_LOG!A:A,A10,MATCH_LOG!B:B,"ADC"),0) -> 0 | K10: =IFERROR(COUNTIFS(MATCH_LOG!A:A,A10,MATCH_LOG!B:B,"SUP",MATCH_LOG!G:G,"승")/COUNTIFS(MATCH_LOG!A:A,A10,MATCH_LOG!B:B,"SUP"),0) -> 0.5 | L10: 애니 | M10: 2 | N10: 누누 | O10: 1 | P10: 베인 | Q10: 1 | R10: =SUMIFS(MATCH_LOG!D:D,MATCH_LOG!A:A,A10) -> 62 | S10: =SUMIFS(MATCH_LOG!E:E,MATCH_LOG!A:A,A10) -> 49 | T10: =SUMIFS(MATCH_LOG!F:F,MATCH_LOG!A:A,A10) -> 72
A11: 성호 | B11: =COUNTIF(MATCH_LOG!A:A,A11) -> 5 | C11: =COUNTIFS(MATCH_LOG!A:A,A11,MATCH_LOG!G:G,"승") -> 2 | D11: =COUNTIFS(MATCH_LOG!A:A,A11,MATCH_LOG!G:G,"패") -> 3 | E11: =IF(B11=0,0,C11/B11) -> 0.4 | F11: =IFERROR((SUMIFS(MATCH_LOG!D:D,MATCH_LOG!A:A,A11)+SUMIFS(MATCH_LOG!F:F,MATCH_LOG!A:A,A11))/SUMIFS(MATCH_LOG!E:E,MATCH_LOG!A:A,A11),0) -> 3.516129 | G11: =IFERROR(COUNTIFS(MATCH_LOG!A:A,A11,MATCH_LOG!B:B,"TOP",MATCH_LOG!G:G,"승")/COUNTIFS(MATCH_LOG!A:A,A11,MATCH_LOG!B:B,"TOP"),0) -> 0 | H11: =IFERROR(COUNTIFS(MATCH_LOG!A:A,A11,MATCH_LOG!B:B,"JG",MATCH_LOG!G:G,"승")/COUNTIFS(MATCH_LOG!A:A,A11,MATCH_LOG!B:B,"JG"),0) -> 0.4 | I11: =IFERROR(COUNTIFS(MATCH_LOG!A:A,A11,MATCH_LOG!B:B,"MID",MATCH_LOG!G:G,"승")/COUNTIFS(MATCH_LOG!A:A,A11,MATCH_LOG!B:B,"MID"),0) -> 0 | J11: =IFERROR(COUNTIFS(MATCH_LOG!A:A,A11,MATCH_LOG!B:B,"ADC",MATCH_LOG!G:G,"승")/COUNTIFS(MATCH_LOG!A:A,A11,MATCH_LOG!B:B,"ADC"),0) -> 0 | K11: =IFERROR(COUNTIFS(MATCH_LOG!A:A,A11,MATCH_LOG!B:B,"SUP",MATCH_LOG!G:G,"승")/COUNTIFS(MATCH_LOG!A:A,A11,MATCH_LOG!B:B,"SUP"),0) -> 0 | L11: 리신 | M11: 1 | N11: 트런들 | O11: 1 | P11: 오공 | Q11: 1 | R11: =SUMIFS(MATCH_LOG!D:D,MATCH_LOG!A:A,A11) -> 40 | S11: =SUMIFS(MATCH_LOG!E:E,MATCH_LOG!A:A,A11) -> 31 | T11: =SUMIFS(MATCH_LOG!F:F,MATCH_LOG!A:A,A11) -> 69
A12: 앤디 | B12: =COUNTIF(MATCH_LOG!A:A,A12) -> 21 | C12: =COUNTIFS(MATCH_LOG!A:A,A12,MATCH_LOG!G:G,"승") -> 13 | D12: =COUNTIFS(MATCH_LOG!A:A,A12,MATCH_LOG!G:G,"패") -> 8 | E12: =IF(B12=0,0,C12/B12) -> 0.61904762 | F12: =IFERROR((SUMIFS(MATCH_LOG!D:D,MATCH_LOG!A:A,A12)+SUMIFS(MATCH_LOG!F:F,MATCH_LOG!A:A,A12))/SUMIFS(MATCH_LOG!E:E,MATCH_LOG!A:A,A12),0) -> 4 | G12: =IFERROR(COUNTIFS(MATCH_LOG!A:A,A12,MATCH_LOG!B:B,"TOP",MATCH_LOG!G:G,"승")/COUNTIFS(MATCH_LOG!A:A,A12,MATCH_LOG!B:B,"TOP"),0) -> 0.5 | H12: =IFERROR(COUNTIFS(MATCH_LOG!A:A,A12,MATCH_LOG!B:B,"JG",MATCH_LOG!G:G,"승")/COUNTIFS(MATCH_LOG!A:A,A12,MATCH_LOG!B:B,"JG"),0) -> 1 | I12: =IFERROR(COUNTIFS(MATCH_LOG!A:A,A12,MATCH_LOG!B:B,"MID",MATCH_LOG!G:G,"승")/COUNTIFS(MATCH_LOG!A:A,A12,MATCH_LOG!B:B,"MID"),0) -> 0.33333333 | J12: =IFERROR(COUNTIFS(MATCH_LOG!A:A,A12,MATCH_LOG!B:B,"ADC",MATCH_LOG!G:G,"승")/COUNTIFS(MATCH_LOG!A:A,A12,MATCH_LOG!B:B,"ADC"),0) -> 0 | K12: =IFERROR(COUNTIFS(MATCH_LOG!A:A,A12,MATCH_LOG!B:B,"SUP",MATCH_LOG!G:G,"승")/COUNTIFS(MATCH_LOG!A:A,A12,MATCH_LOG!B:B,"SUP"),0) -> 0.71428571 | L12: 브라움 | M12: 3 | N12: 아리 | O12: 2 | P12: 파이크 | Q12: 2 | R12: =SUMIFS(MATCH_LOG!D:D,MATCH_LOG!A:A,A12) -> 88 | S12: =SUMIFS(MATCH_LOG!E:E,MATCH_LOG!A:A,A12) -> 89 | T12: =SUMIFS(MATCH_LOG!F:F,MATCH_LOG!A:A,A12) -> 268
A13: 상원 | B13: =COUNTIF(MATCH_LOG!A:A,A13) -> 26 | C13: =COUNTIFS(MATCH_LOG!A:A,A13,MATCH_LOG!G:G,"승") -> 18 | D13: =COUNTIFS(MATCH_LOG!A:A,A13,MATCH_LOG!G:G,"패") -> 8 | E13: =IF(B13=0,0,C13/B13) -> 0.69230769 | F13: =IFERROR((SUMIFS(MATCH_LOG!D:D,MATCH_LOG!A:A,A13)+SUMIFS(MATCH_LOG!F:F,MATCH_LOG!A:A,A13))/SUMIFS(MATCH_LOG!E:E,MATCH_LOG!A:A,A13),0) -> 3.7864078 | G13: =IFERROR(COUNTIFS(MATCH_LOG!A:A,A13,MATCH_LOG!B:B,"TOP",MATCH_LOG!G:G,"승")/COUNTIFS(MATCH_LOG!A:A,A13,MATCH_LOG!B:B,"TOP"),0) -> 0 | H13: =IFERROR(COUNTIFS(MATCH_LOG!A:A,A13,MATCH_LOG!B:B,"JG",MATCH_LOG!G:G,"승")/COUNTIFS(MATCH_LOG!A:A,A13,MATCH_LOG!B:B,"JG"),0) -> 0 | I13: =IFERROR(COUNTIFS(MATCH_LOG!A:A,A13,MATCH_LOG!B:B,"MID",MATCH_LOG!G:G,"승")/COUNTIFS(MATCH_LOG!A:A,A13,MATCH_LOG!B:B,"MID"),0) -> 0 | J13: =IFERROR(COUNTIFS(MATCH_LOG!A:A,A13,MATCH_LOG!B:B,"ADC",MATCH_LOG!G:G,"승")/COUNTIFS(MATCH_LOG!A:A,A13,MATCH_LOG!B:B,"ADC"),0) -> 0.69230769 | K13: =IFERROR(COUNTIFS(MATCH_LOG!A:A,A13,MATCH_LOG!B:B,"SUP",MATCH_LOG!G:G,"승")/COUNTIFS(MATCH_LOG!A:A,A13,MATCH_LOG!B:B,"SUP"),0) -> 0 | L13: 스몰더 | M13: 9 | N13: 루시안 | O13: 4 | P13: 이즈리얼 | Q13: 2 | R13: =SUMIFS(MATCH_LOG!D:D,MATCH_LOG!A:A,A13) -> 193 | S13: =SUMIFS(MATCH_LOG!E:E,MATCH_LOG!A:A,A13) -> 103 | T13: =SUMIFS(MATCH_LOG!F:F,MATCH_LOG!A:A,A13) -> 197
... A18: JW | B18: =COUNTIF(MATCH_LOG!A:A,A18) -> 9 | C18: =COUNTIFS(MATCH_LOG!A:A,A18,MATCH_LOG!G:G,"승") -> 3 | D18: =COUNTIFS(MATCH_LOG!A:A,A18,MATCH_LOG!G:G,"패") -> 6 | E18: =IF(B18=0,0,C18/B18) -> 0.33333333 | F18: =IFERROR((SUMIFS(MATCH_LOG!D:D,MATCH_LOG!A:A,A18)+SUMIFS(MATCH_LOG!F:F,MATCH_LOG!A:A,A18))/SUMIFS(MATCH_LOG!E:E,MATCH_LOG!A:A,A18),0) -> 2.296875 | G18: =IFERROR(COUNTIFS(MATCH_LOG!A:A,A18,MATCH_LOG!B:B,"TOP",MATCH_LOG!G:G,"승")/COUNTIFS(MATCH_LOG!A:A,A18,MATCH_LOG!B:B,"TOP"),0) -> 0 | H18: =IFERROR(COUNTIFS(MATCH_LOG!A:A,A18,MATCH_LOG!B:B,"JG",MATCH_LOG!G:G,"승")/COUNTIFS(MATCH_LOG!A:A,A18,MATCH_LOG!B:B,"JG"),0) -> 0.2 | I18: =IFERROR(COUNTIFS(MATCH_LOG!A:A,A18,MATCH_LOG!B:B,"MID",MATCH_LOG!G:G,"승")/COUNTIFS(MATCH_LOG!A:A,A18,MATCH_LOG!B:B,"MID"),0) -> 0 | J18: =IFERROR(COUNTIFS(MATCH_LOG!A:A,A18,MATCH_LOG!B:B,"ADC",MATCH_LOG!G:G,"승")/COUNTIFS(MATCH_LOG!A:A,A18,MATCH_LOG!B:B,"ADC"),0) -> 0.5 | K18: =IFERROR(COUNTIFS(MATCH_LOG!A:A,A18,MATCH_LOG!B:B,"SUP",MATCH_LOG!G:G,"승")/COUNTIFS(MATCH_LOG!A:A,A18,MATCH_LOG!B:B,"SUP"),0) -> 0 | L18: 리신 | M18: 2 | N18: 바이 | O18: 1 | P18: 제드 | Q18: 1 | R18: =SUMIFS(MATCH_LOG!D:D,MATCH_LOG!A:A,A18) -> 81 | S18: =SUMIFS(MATCH_LOG!E:E,MATCH_LOG!A:A,A18) -> 64 | T18: =SUMIFS(MATCH_LOG!F:F,MATCH_LOG!A:A,A18) -> 66
A19: 조훈 | B19: =COUNTIF(MATCH_LOG!A:A,A19) -> 2 | C19: =COUNTIFS(MATCH_LOG!A:A,A19,MATCH_LOG!G:G,"승") -> 2 | D19: =COUNTIFS(MATCH_LOG!A:A,A19,MATCH_LOG!G:G,"패") -> 0 | E19: =IF(B19=0,0,C19/B19) -> 1 | F19: =IFERROR((SUMIFS(MATCH_LOG!D:D,MATCH_LOG!A:A,A19)+SUMIFS(MATCH_LOG!F:F,MATCH_LOG!A:A,A19))/SUMIFS(MATCH_LOG!E:E,MATCH_LOG!A:A,A19),0) -> 2.8 | G19: =IFERROR(COUNTIFS(MATCH_LOG!A:A,A19,MATCH_LOG!B:B,"TOP",MATCH_LOG!G:G,"승")/COUNTIFS(MATCH_LOG!A:A,A19,MATCH_LOG!B:B,"TOP"),0) -> 0 | H19: =IFERROR(COUNTIFS(MATCH_LOG!A:A,A19,MATCH_LOG!B:B,"JG",MATCH_LOG!G:G,"승")/COUNTIFS(MATCH_LOG!A:A,A19,MATCH_LOG!B:B,"JG"),0) -> 1 | I19: =IFERROR(COUNTIFS(MATCH_LOG!A:A,A19,MATCH_LOG!B:B,"MID",MATCH_LOG!G:G,"승")/COUNTIFS(MATCH_LOG!A:A,A19,MATCH_LOG!B:B,"MID"),0) -> 0 | J19: =IFERROR(COUNTIFS(MATCH_LOG!A:A,A19,MATCH_LOG!B:B,"ADC",MATCH_LOG!G:G,"승")/COUNTIFS(MATCH_LOG!A:A,A19,MATCH_LOG!B:B,"ADC"),0) -> 0 | K19: =IFERROR(COUNTIFS(MATCH_LOG!A:A,A19,MATCH_LOG!B:B,"SUP",MATCH_LOG!G:G,"승")/COUNTIFS(MATCH_LOG!A:A,A19,MATCH_LOG!B:B,"SUP"),0) -> 0 | L19: 오공 | M19: 1 | N19: 신짜오 | O19: 1 | R19: =SUMIFS(MATCH_LOG!D:D,MATCH_LOG!A:A,A19) -> 17 | S19: =SUMIFS(MATCH_LOG!E:E,MATCH_LOG!A:A,A19) -> 10 | T19: =SUMIFS(MATCH_LOG!F:F,MATCH_LOG!A:A,A19) -> 11
A20: 세준 | B20: =COUNTIF(MATCH_LOG!A:A,A20) -> 17 | C20: =COUNTIFS(MATCH_LOG!A:A,A20,MATCH_LOG!G:G,"승") -> 10 | D20: =COUNTIFS(MATCH_LOG!A:A,A20,MATCH_LOG!G:G,"패") -> 7 | E20: =IF(B20=0,0,C20/B20) -> 0.58823529 | F20: =IFERROR((SUMIFS(MATCH_LOG!D:D,MATCH_LOG!A:A,A20)+SUMIFS(MATCH_LOG!F:F,MATCH_LOG!A:A,A20))/SUMIFS(MATCH_LOG!E:E,MATCH_LOG!A:A,A20),0) -> 3.0930233 | G20: =IFERROR(COUNTIFS(MATCH_LOG!A:A,A20,MATCH_LOG!B:B,"TOP",MATCH_LOG!G:G,"승")/COUNTIFS(MATCH_LOG!A:A,A20,MATCH_LOG!B:B,"TOP"),0) -> 0.83333333 | H20: =IFERROR(COUNTIFS(MATCH_LOG!A:A,A20,MATCH_LOG!B:B,"JG",MATCH_LOG!G:G,"승")/COUNTIFS(MATCH_LOG!A:A,A20,MATCH_LOG!B:B,"JG"),0) -> 0 | I20: =IFERROR(COUNTIFS(MATCH_LOG!A:A,A20,MATCH_LOG!B:B,"MID",MATCH_LOG!G:G,"승")/COUNTIFS(MATCH_LOG!A:A,A20,MATCH_LOG!B:B,"MID"),0) -> 0.5 | J20: =IFERROR(COUNTIFS(MATCH_LOG!A:A,A20,MATCH_LOG!B:B,"ADC",MATCH_LOG!G:G,"승")/COUNTIFS(MATCH_LOG!A:A,A20,MATCH_LOG!B:B,"ADC"),0) -> 0.5 | K20: =IFERROR(COUNTIFS(MATCH_LOG!A:A,A20,MATCH_LOG!B:B,"SUP",MATCH_LOG!G:G,"승")/COUNTIFS(MATCH_LOG!A:A,A20,MATCH_LOG!B:B,"SUP"),0) -> 0 | L20: 암베사 | M20: 4 | N20: 아트록스 | O20: 4 | P20: 아리 | Q20: 2 | R20: =SUMIFS(MATCH_LOG!D:D,MATCH_LOG!A:A,A20) -> 145 | S20: =SUMIFS(MATCH_LOG!E:E,MATCH_LOG!A:A,A20) -> 86 | T20: =SUMIFS(MATCH_LOG!F:F,MATCH_LOG!A:A,A20) -> 121
A21: 망수 | B21: =COUNTIF(MATCH_LOG!A:A,A21) -> 18 | C21: =COUNTIFS(MATCH_LOG!A:A,A21,MATCH_LOG!G:G,"승") -> 9 | D21: =COUNTIFS(MATCH_LOG!A:A,A21,MATCH_LOG!G:G,"패") -> 9 | E21: =IF(B21=0,0,C21/B21) -> 0.5 | F21: =IFERROR((SUMIFS(MATCH_LOG!D:D,MATCH_LOG!A:A,A21)+SUMIFS(MATCH_LOG!F:F,MATCH_LOG!A:A,A21))/SUMIFS(MATCH_LOG!E:E,MATCH_LOG!A:A,A21),0) -> 1.3106061 | G21: =IFERROR(COUNTIFS(MATCH_LOG!A:A,A21,MATCH_LOG!B:B,"TOP",MATCH_LOG!G:G,"승")/COUNTIFS(MATCH_LOG!A:A,A21,MATCH_LOG!B:B,"TOP"),0) -> 0.125 | H21: =IFERROR(COUNTIFS(MATCH_LOG!A:A,A21,MATCH_LOG!B:B,"JG",MATCH_LOG!G:G,"승")/COUNTIFS(MATCH_LOG!A:A,A21,MATCH_LOG!B:B,"JG"),0) -> 0.875 | I21: =IFERROR(COUNTIFS(MATCH_LOG!A:A,A21,MATCH_LOG!B:B,"MID",MATCH_LOG!G:G,"승")/COUNTIFS(MATCH_LOG!A:A,A21,MATCH_LOG!B:B,"MID"),0) -> 1 | J21: =IFERROR(COUNTIFS(MATCH_LOG!A:A,A21,MATCH_LOG!B:B,"ADC",MATCH_LOG!G:G,"승")/COUNTIFS(MATCH_LOG!A:A,A21,MATCH_LOG!B:B,"ADC"),0) -> 0 | K21: =IFERROR(COUNTIFS(MATCH_LOG!A:A,A21,MATCH_LOG!B:B,"SUP",MATCH_LOG!G:G,"승")/COUNTIFS(MATCH_LOG!A:A,A21,MATCH_LOG!B:B,"SUP"),0) -> 0 | L21: 리신 | M21: 2 | N21: 탈론 | O21: 2 | P21: 올라프 | Q21: 1 | R21: =SUMIFS(MATCH_LOG!D:D,MATCH_LOG!A:A,A21) -> 85 | S21: =SUMIFS(MATCH_LOG!E:E,MATCH_LOG!A:A,A21) -> 132 | T21: =SUMIFS(MATCH_LOG!F:F,MATCH_LOG!A:A,A21) -> 88
A22: 엔티 | B22: =COUNTIF(MATCH_LOG!A:A,A22) -> 13 | C22: =COUNTIFS(MATCH_LOG!A:A,A22,MATCH_LOG!G:G,"승") -> 5 | D22: =COUNTIFS(MATCH_LOG!A:A,A22,MATCH_LOG!G:G,"패") -> 8 | E22: =IF(B22=0,0,C22/B22) -> 0.38461538 | F22: =IFERROR((SUMIFS(MATCH_LOG!D:D,MATCH_LOG!A:A,A22)+SUMIFS(MATCH_LOG!F:F,MATCH_LOG!A:A,A22))/SUMIFS(MATCH_LOG!E:E,MATCH_LOG!A:A,A22),0) -> 1.7411765 | G22: =IFERROR(COUNTIFS(MATCH_LOG!A:A,A22,MATCH_LOG!B:B,"TOP",MATCH_LOG!G:G,"승")/COUNTIFS(MATCH_LOG!A:A,A22,MATCH_LOG!B:B,"TOP"),0) -> 0.33333333 | H22: =IFERROR(COUNTIFS(MATCH_LOG!A:A,A22,MATCH_LOG!B:B,"JG",MATCH_LOG!G:G,"승")/COUNTIFS(MATCH_LOG!A:A,A22,MATCH_LOG!B:B,"JG"),0) -> 0.5 | I22: =IFERROR(COUNTIFS(MATCH_LOG!A:A,A22,MATCH_LOG!B:B,"MID",MATCH_LOG!G:G,"승")/COUNTIFS(MATCH_LOG!A:A,A22,MATCH_LOG!B:B,"MID"),0) -> 0.28571429 | J22: =IFERROR(COUNTIFS(MATCH_LOG!A:A,A22,MATCH_LOG!B:B,"ADC",MATCH_LOG!G:G,"승")/COUNTIFS(MATCH_LOG!A:A,A22,MATCH_LOG!B:B,"ADC"),0) -> 0 | K22: =IFERROR(COUNTIFS(MATCH_LOG!A:A,A22,MATCH_LOG!B:B,"SUP",MATCH_LOG!G:G,"승")/COUNTIFS(MATCH_LOG!A:A,A22,MATCH_LOG!B:B,"SUP"),0) -> 1 | L22: 사이온 | M22: 4 | N22: 레넥톤 | O22: 2 | P22: 오리아나 | Q22: 1 | R22: =SUMIFS(MATCH_LOG!D:D,MATCH_LOG!A:A,A22) -> 44 | S22: =SUMIFS(MATCH_LOG!E:E,MATCH_LOG!A:A,A22) -> 85 | T22: =SUMIFS(MATCH_LOG!F:F,MATCH_LOG!A:A,A22) -> 104
A23: 상기 | B23: =COUNTIF(MATCH_LOG!A:A,A23) -> 12 | C23: =COUNTIFS(MATCH_LOG!A:A,A23,MATCH_LOG!G:G,"승") -> 7 | D23: =COUNTIFS(MATCH_LOG!A:A,A23,MATCH_LOG!G:G,"패") -> 5 | E23: =IF(B23=0,0,C23/B23) -> 0.58333333 | F23: =IFERROR((SUMIFS(MATCH_LOG!D:D,MATCH_LOG!A:A,A23)+SUMIFS(MATCH_LOG!F:F,MATCH_LOG!A:A,A23))/SUMIFS(MATCH_LOG!E:E,MATCH_LOG!A:A,A23),0) -> 2.1621622 | G23: =IFERROR(COUNTIFS(MATCH_LOG!A:A,A23,MATCH_LOG!B:B,"TOP",MATCH_LOG!G:G,"승")/COUNTIFS(MATCH_LOG!A:A,A23,MATCH_LOG!B:B,"TOP"),0) -> 0.5 | H23: =IFERROR(COUNTIFS(MATCH_LOG!A:A,A23,MATCH_LOG!B:B,"JG",MATCH_LOG!G:G,"승")/COUNTIFS(MATCH_LOG!A:A,A23,MATCH_LOG!B:B,"JG"),0) -> 0 | I23: =IFERROR(COUNTIFS(MATCH_LOG!A:A,A23,MATCH_LOG!B:B,"MID",MATCH_LOG!G:G,"승")/COUNTIFS(MATCH_LOG!A:A,A23,MATCH_LOG!B:B,"MID"),0) -> 0 | J23: =IFERROR(COUNTIFS(MATCH_LOG!A:A,A23,MATCH_LOG!B:B,"ADC",MATCH_LOG!G:G,"승")/COUNTIFS(MATCH_LOG!A:A,A23,MATCH_LOG!B:B,"ADC"),0) -> 0 | K23: =IFERROR(COUNTIFS(MATCH_LOG!A:A,A23,MATCH_LOG!B:B,"SUP",MATCH_LOG!G:G,"승")/COUNTIFS(MATCH_LOG!A:A,A23,MATCH_LOG!B:B,"SUP"),0) -> 0.75 | L23: 크산테 | M23: 4 | N23: 스카너 | O23: 1 | P23: 오른 | Q23: 1 | R23: =SUMIFS(MATCH_LOG!D:D,MATCH_LOG!A:A,A23) -> 53 | S23: =SUMIFS(MATCH_LOG!E:E,MATCH_LOG!A:A,A23) -> 74 | T23: =SUMIFS(MATCH_LOG!F:F,MATCH_LOG!A:A,A23) -> 107
A24: 지지 | B24: =COUNTIF(MATCH_LOG!A:A,A24) -> 34 | C24: =COUNTIFS(MATCH_LOG!A:A,A24,MATCH_LOG!G:G,"승") -> 17 | D24: =COUNTIFS(MATCH_LOG!A:A,A24,MATCH_LOG!G:G,"패") -> 17 | E24: =IF(B24=0,0,C24/B24) -> 0.5 | F24: =IFERROR((SUMIFS(MATCH_LOG!D:D,MATCH_LOG!A:A,A24)+SUMIFS(MATCH_LOG!F:F,MATCH_LOG!A:A,A24))/SUMIFS(MATCH_LOG!E:E,MATCH_LOG!A:A,A24),0) -> 1.5826446 | G24: =IFERROR(COUNTIFS(MATCH_LOG!A:A,A24,MATCH_LOG!B:B,"TOP",MATCH_LOG!G:G,"승")/COUNTIFS(MATCH_LOG!A:A,A24,MATCH_LOG!B:B,"TOP"),0) -> 0.5 | H24: =IFERROR(COUNTIFS(MATCH_LOG!A:A,A24,MATCH_LOG!B:B,"JG",MATCH_LOG!G:G,"승")/COUNTIFS(MATCH_LOG!A:A,A24,MATCH_LOG!B:B,"JG"),0) -> 0 | I24: =IFERROR(COUNTIFS(MATCH_LOG!A:A,A24,MATCH_LOG!B:B,"MID",MATCH_LOG!G:G,"승")/COUNTIFS(MATCH_LOG!A:A,A24,MATCH_LOG!B:B,"MID"),0) -> 0 | J24: =IFERROR(COUNTIFS(MATCH_LOG!A:A,A24,MATCH_LOG!B:B,"ADC",MATCH_LOG!G:G,"승")/COUNTIFS(MATCH_LOG!A:A,A24,MATCH_LOG!B:B,"ADC"),0) -> 0.75 | K24: =IFERROR(COUNTIFS(MATCH_LOG!A:A,A24,MATCH_LOG!B:B,"SUP",MATCH_LOG!G:G,"승")/COUNTIFS(MATCH_LOG!A:A,A24,MATCH_LOG!B:B,"SUP"),0) -> 0 | L24: 크산테 | M24: 8 | N24: 잭스 | O24: 4 | P24: 레넥톤 | Q24: 3 | R24: =SUMIFS(MATCH_LOG!D:D,MATCH_LOG!A:A,A24) -> 153 | S24: =SUMIFS(MATCH_LOG!E:E,MATCH_LOG!A:A,A24) -> 242 | T24: =SUMIFS(MATCH_LOG!F:F,MATCH_LOG!A:A,A24) -> 230
A25: 승한 | B25: =COUNTIF(MATCH_LOG!A:A,A25) -> 4 | C25: =COUNTIFS(MATCH_LOG!A:A,A25,MATCH_LOG!G:G,"승") -> 1 | D25: =COUNTIFS(MATCH_LOG!A:A,A25,MATCH_LOG!G:G,"패") -> 3 | E25: =IF(B25=0,0,C25/B25) -> 0.25 | F25: =IFERROR((SUMIFS(MATCH_LOG!D:D,MATCH_LOG!A:A,A25)+SUMIFS(MATCH_LOG!F:F,MATCH_LOG!A:A,A25))/SUMIFS(MATCH_LOG!E:E,MATCH_LOG!A:A,A25),0) -> 2 | G25: =IFERROR(COUNTIFS(MATCH_LOG!A:A,A25,MATCH_LOG!B:B,"TOP",MATCH_LOG!G:G,"승")/COUNTIFS(MATCH_LOG!A:A,A25,MATCH_LOG!B:B,"TOP"),0) -> 0 | H25: =IFERROR(COUNTIFS(MATCH_LOG!A:A,A25,MATCH_LOG!B:B,"JG",MATCH_LOG!G:G,"승")/COUNTIFS(MATCH_LOG!A:A,A25,MATCH_LOG!B:B,"JG"),0) -> 0 | I25: =IFERROR(COUNTIFS(MATCH_LOG!A:A,A25,MATCH_LOG!B:B,"MID",MATCH_LOG!G:G,"승")/COUNTIFS(MATCH_LOG!A:A,A25,MATCH_LOG!B:B,"MID"),0) -> 1 | J25: =IFERROR(COUNTIFS(MATCH_LOG!A:A,A25,MATCH_LOG!B:B,"ADC",MATCH_LOG!G:G,"승")/COUNTIFS(MATCH_LOG!A:A,A25,MATCH_LOG!B:B,"ADC"),0) -> 0 | K25: =IFERROR(COUNTIFS(MATCH_LOG!A:A,A25,MATCH_LOG!B:B,"SUP",MATCH_LOG!G:G,"승")/COUNTIFS(MATCH_LOG!A:A,A25,MATCH_LOG!B:B,"SUP"),0) -> 0 | L25: 신짜오 | M25: 1 | N25: 자크 | O25: 1 | P25: 말파이트 | Q25: 1 | R25: =SUMIFS(MATCH_LOG!D:D,MATCH_LOG!A:A,A25) -> 19 | S25: =SUMIFS(MATCH_LOG!E:E,MATCH_LOG!A:A,A25) -> 22 | T25: =SUMIFS(MATCH_LOG!F:F,MATCH_LOG!A:A,A25) -> 25
A26: 시로 | B26: =COUNTIF(MATCH_LOG!A:A,A26) -> 26 | C26: =COUNTIFS(MATCH_LOG!A:A,A26,MATCH_LOG!G:G,"승") -> 16 | D26: =COUNTIFS(MATCH_LOG!A:A,A26,MATCH_LOG!G:G,"패") -> 10 | E26: =IF(B26=0,0,C26/B26) -> 0.61538462 | F26: =IFERROR((SUMIFS(MATCH_LOG!D:D,MATCH_LOG!A:A,A26)+SUMIFS(MATCH_LOG!F:F,MATCH_LOG!A:A,A26))/SUMIFS(MATCH_LOG!E:E,MATCH_LOG!A:A,A26),0) -> 2.5953757 | G26: =IFERROR(COUNTIFS(MATCH_LOG!A:A,A26,MATCH_LOG!B:B,"TOP",MATCH_LOG!G:G,"승")/COUNTIFS(MATCH_LOG!A:A,A26,MATCH_LOG!B:B,"TOP"),0) -> 0.5 | H26: =IFERROR(COUNTIFS(MATCH_LOG!A:A,A26,MATCH_LOG!B:B,"JG",MATCH_LOG!G:G,"승")/COUNTIFS(MATCH_LOG!A:A,A26,MATCH_LOG!B:B,"JG"),0) -> 0.72727273 | I26: =IFERROR(COUNTIFS(MATCH_LOG!A:A,A26,MATCH_LOG!B:B,"MID",MATCH_LOG!G:G,"승")/COUNTIFS(MATCH_LOG!A:A,A26,MATCH_LOG!B:B,"MID"),0) -> 0.5 | J26: =IFERROR(COUNTIFS(MATCH_LOG!A:A,A26,MATCH_LOG!B:B,"ADC",MATCH_LOG!G:G,"승")/COUNTIFS(MATCH_LOG!A:A,A26,MATCH_LOG!B:B,"ADC"),0) -> 0 | K26: =IFERROR(COUNTIFS(MATCH_LOG!A:A,A26,MATCH_LOG!B:B,"SUP",MATCH_LOG!G:G,"승")/COUNTIFS(MATCH_LOG!A:A,A26,MATCH_LOG!B:B,"SUP"),0) -> 1 | L26: 신짜오 | M26: 5 | N26: 리신 | O26: 5 | P26: 모데카이저 | Q26: 2 | R26: =SUMIFS(MATCH_LOG!D:D,MATCH_LOG!A:A,A26) -> 181 | S26: =SUMIFS(MATCH_LOG!E:E,MATCH_LOG!A:A,A26) -> 173 | T26: =SUMIFS(MATCH_LOG!F:F,MATCH_LOG!A:A,A26) -> 268
A27: 나닌너 | B27: =COUNTIF(MATCH_LOG!A:A,A27) -> 12 | C27: =COUNTIFS(MATCH_LOG!A:A,A27,MATCH_LOG!G:G,"승") -> 6 | D27: =COUNTIFS(MATCH_LOG!A:A,A27,MATCH_LOG!G:G,"패") -> 6 | E27: =IF(B27=0,0,C27/B27) -> 0.5 | F27: =IFERROR((SUMIFS(MATCH_LOG!D:D,MATCH_LOG!A:A,A27)+SUMIFS(MATCH_LOG!F:F,MATCH_LOG!A:A,A27))/SUMIFS(MATCH_LOG!E:E,MATCH_LOG!A:A,A27),0) -> 2.2272727 | G27: =IFERROR(COUNTIFS(MATCH_LOG!A:A,A27,MATCH_LOG!B:B,"TOP",MATCH_LOG!G:G,"승")/COUNTIFS(MATCH_LOG!A:A,A27,MATCH_LOG!B:B,"TOP"),0) -> 0 | H27: =IFERROR(COUNTIFS(MATCH_LOG!A:A,A27,MATCH_LOG!B:B,"JG",MATCH_LOG!G:G,"승")/COUNTIFS(MATCH_LOG!A:A,A27,MATCH_LOG!B:B,"JG"),0) -> 0.66666667 | I27: =IFERROR(COUNTIFS(MATCH_LOG!A:A,A27,MATCH_LOG!B:B,"MID",MATCH_LOG!G:G,"승")/COUNTIFS(MATCH_LOG!A:A,A27,MATCH_LOG!B:B,"MID"),0) -> 1 | J27: =IFERROR(COUNTIFS(MATCH_LOG!A:A,A27,MATCH_LOG!B:B,"ADC",MATCH_LOG!G:G,"승")/COUNTIFS(MATCH_LOG!A:A,A27,MATCH_LOG!B:B,"ADC"),0) -> 0 | K27: =IFERROR(COUNTIFS(MATCH_LOG!A:A,A27,MATCH_LOG!B:B,"SUP",MATCH_LOG!G:G,"승")/COUNTIFS(MATCH_LOG!A:A,A27,MATCH_LOG!B:B,"SUP"),0) -> 0.28571429 | L27: 알리스타 | M27: 2 | N27: 노틸러스 | O27: 2 | P27: 다이애나 | Q27: 2 | R27: =SUMIFS(MATCH_LOG!D:D,MATCH_LOG!A:A,A27) -> 22 | S27: =SUMIFS(MATCH_LOG!E:E,MATCH_LOG!A:A,A27) -> 66 | T27: =SUMIFS(MATCH_LOG!F:F,MATCH_LOG!A:A,A27) -> 125
A28: 준영 | B28: =COUNTIF(MATCH_LOG!A:A,A28) -> 6 | C28: =COUNTIFS(MATCH_LOG!A:A,A28,MATCH_LOG!G:G,"승") -> 1 | D28: =COUNTIFS(MATCH_LOG!A:A,A28,MATCH_LOG!G:G,"패") -> 5 | E28: =IF(B28=0,0,C28/B28) -> 0.16666667 | F28: =IFERROR((SUMIFS(MATCH_LOG!D:D,MATCH_LOG!A:A,A28)+SUMIFS(MATCH_LOG!F:F,MATCH_LOG!A:A,A28))/SUMIFS(MATCH_LOG!E:E,MATCH_LOG!A:A,A28),0) -> 1.4571429 | G28: =IFERROR(COUNTIFS(MATCH_LOG!A:A,A28,MATCH_LOG!B:B,"TOP",MATCH_LOG!G:G,"승")/COUNTIFS(MATCH_LOG!A:A,A28,MATCH_LOG!B:B,"TOP"),0) -> 0 | H28: =IFERROR(COUNTIFS(MATCH_LOG!A:A,A28,MATCH_LOG!B:B,"JG",MATCH_LOG!G:G,"승")/COUNTIFS(MATCH_LOG!A:A,A28,MATCH_LOG!B:B,"JG"),0) -> 0 | I28: =IFERROR(COUNTIFS(MATCH_LOG!A:A,A28,MATCH_LOG!B:B,"MID",MATCH_LOG!G:G,"승")/COUNTIFS(MATCH_LOG!A:A,A28,MATCH_LOG!B:B,"MID"),0) -> 0 | J28: =IFERROR(COUNTIFS(MATCH_LOG!A:A,A28,MATCH_LOG!B:B,"ADC",MATCH_LOG!G:G,"승")/COUNTIFS(MATCH_LOG!A:A,A28,MATCH_LOG!B:B,"ADC"),0) -> 0 | K28: =IFERROR(COUNTIFS(MATCH_LOG!A:A,A28,MATCH_LOG!B:B,"SUP",MATCH_LOG!G:G,"승")/COUNTIFS(MATCH_LOG!A:A,A28,MATCH_LOG!B:B,"SUP"),0) -> 0.2 | L28: 세나 | M28: 1 | N28: 바이 | O28: 1 | P28: 카르마 | Q28: 1 | R28: =SUMIFS(MATCH_LOG!D:D,MATCH_LOG!A:A,A28) -> 7 | S28: =SUMIFS(MATCH_LOG!E:E,MATCH_LOG!A:A,A28) -> 35 | T28: =SUMIFS(MATCH_LOG!F:F,MATCH_LOG!A:A,A28) -> 44
A29: 칸쵸 | B29: =COUNTIF(MATCH_LOG!A:A,A29) -> 3 | C29: =COUNTIFS(MATCH_LOG!A:A,A29,MATCH_LOG!G:G,"승") -> 1 | D29: =COUNTIFS(MATCH_LOG!A:A,A29,MATCH_LOG!G:G,"패") -> 2 | E29: =IF(B29=0,0,C29/B29) -> 0.33333333 | F29: =IFERROR((SUMIFS(MATCH_LOG!D:D,MATCH_LOG!A:A,A29)+SUMIFS(MATCH_LOG!F:F,MATCH_LOG!A:A,A29))/SUMIFS(MATCH_LOG!E:E,MATCH_LOG!A:A,A29),0) -> 1.4074074 | G29: =IFERROR(COUNTIFS(MATCH_LOG!A:A,A29,MATCH_LOG!B:B,"TOP",MATCH_LOG!G:G,"승")/COUNTIFS(MATCH_LOG!A:A,A29,MATCH_LOG!B:B,"TOP"),0) -> 0.33333333 | H29: =IFERROR(COUNTIFS(MATCH_LOG!A:A,A29,MATCH_LOG!B:B,"JG",MATCH_LOG!G:G,"승")/COUNTIFS(MATCH_LOG!A:A,A29,MATCH_LOG!B:B,"JG"),0) -> 0 | I29: =IFERROR(COUNTIFS(MATCH_LOG!A:A,A29,MATCH_LOG!B:B,"MID",MATCH_LOG!G:G,"승")/COUNTIFS(MATCH_LOG!A:A,A29,MATCH_LOG!B:B,"MID"),0) -> 0 | J29: =IFERROR(COUNTIFS(MATCH_LOG!A:A,A29,MATCH_LOG!B:B,"ADC",MATCH_LOG!G:G,"승")/COUNTIFS(MATCH_LOG!A:A,A29,MATCH_LOG!B:B,"ADC"),0) -> 0 | K29: =IFERROR(COUNTIFS(MATCH_LOG!A:A,A29,MATCH_LOG!B:B,"SUP",MATCH_LOG!G:G,"승")/COUNTIFS(MATCH_LOG!A:A,A29,MATCH_LOG!B:B,"SUP"),0) -> 0 | L29: 오른 | M29: 1 | N29: 다리우스 | O29: 1 | P29: 볼리베어 | Q29: 1 | R29: =SUMIFS(MATCH_LOG!D:D,MATCH_LOG!A:A,A29) -> 13 | S29: =SUMIFS(MATCH_LOG!E:E,MATCH_LOG!A:A,A29) -> 27 | T29: =SUMIFS(MATCH_LOG!F:F,MATCH_LOG!A:A,A29) -> 25
A30: 민서 | B30: =COUNTIF(MATCH_LOG!A:A,A30) -> 2 | C30: =COUNTIFS(MATCH_LOG!A:A,A30,MATCH_LOG!G:G,"승") -> 2 | D30: =COUNTIFS(MATCH_LOG!A:A,A30,MATCH_LOG!G:G,"패") -> 0 | E30: =IF(B30=0,0,C30/B30) -> 1 | F30: =IFERROR((SUMIFS(MATCH_LOG!D:D,MATCH_LOG!A:A,A30)+SUMIFS(MATCH_LOG!F:F,MATCH_LOG!A:A,A30))/SUMIFS(MATCH_LOG!E:E,MATCH_LOG!A:A,A30),0) -> 1.5 | G30: =IFERROR(COUNTIFS(MATCH_LOG!A:A,A30,MATCH_LOG!B:B,"TOP",MATCH_LOG!G:G,"승")/COUNTIFS(MATCH_LOG!A:A,A30,MATCH_LOG!B:B,"TOP"),0) -> 1 | H30: =IFERROR(COUNTIFS(MATCH_LOG!A:A,A30,MATCH_LOG!B:B,"JG",MATCH_LOG!G:G,"승")/COUNTIFS(MATCH_LOG!A:A,A30,MATCH_LOG!B:B,"JG"),0) -> 0 | I30: =IFERROR(COUNTIFS(MATCH_LOG!A:A,A30,MATCH_LOG!B:B,"MID",MATCH_LOG!G:G,"승")/COUNTIFS(MATCH_LOG!A:A,A30,MATCH_LOG!B:B,"MID"),0) -> 1 | J30: =IFERROR(COUNTIFS(MATCH_LOG!A:A,A30,MATCH_LOG!B:B,"ADC",MATCH_LOG!G:G,"승")/COUNTIFS(MATCH_LOG!A:A,A30,MATCH_LOG!B:B,"ADC"),0) -> 0 | K30: =IFERROR(COUNTIFS(MATCH_LOG!A:A,A30,MATCH_LOG!B:B,"SUP",MATCH_LOG!G:G,"승")/COUNTIFS(MATCH_LOG!A:A,A30,MATCH_LOG!B:B,"SUP"),0) -> 0 | L30: 오로라 | M30: 1 | N30: 브랜드 | O30: 1 | R30: =SUMIFS(MATCH_LOG!D:D,MATCH_LOG!A:A,A30) -> 5 | S30: =SUMIFS(MATCH_LOG!E:E,MATCH_LOG!A:A,A30) -> 6 | T30: =SUMIFS(MATCH_LOG!F:F,MATCH_LOG!A:A,A30) -> 4
A31: 유현 | B31: =COUNTIF(MATCH_LOG!A:A,A31) -> 30 | C31: =COUNTIFS(MATCH_LOG!A:A,A31,MATCH_LOG!G:G,"승") -> 16 | D31: =COUNTIFS(MATCH_LOG!A:A,A31,MATCH_LOG!G:G,"패") -> 14 | E31: =IF(B31=0,0,C31/B31) -> 0.53333333 | F31: =IFERROR((SUMIFS(MATCH_LOG!D:D,MATCH_LOG!A:A,A31)+SUMIFS(MATCH_LOG!F:F,MATCH_LOG!A:A,A31))/SUMIFS(MATCH_LOG!E:E,MATCH_LOG!A:A,A31),0) -> 2.9770992 | G31: =IFERROR(COUNTIFS(MATCH_LOG!A:A,A31,MATCH_LOG!B:B,"TOP",MATCH_LOG!G:G,"승")/COUNTIFS(MATCH_LOG!A:A,A31,MATCH_LOG!B:B,"TOP"),0) -> 0 | H31: =IFERROR(COUNTIFS(MATCH_LOG!A:A,A31,MATCH_LOG!B:B,"JG",MATCH_LOG!G:G,"승")/COUNTIFS(MATCH_LOG!A:A,A31,MATCH_LOG!B:B,"JG"),0) -> 0 | I31: =IFERROR(COUNTIFS(MATCH_LOG!A:A,A31,MATCH_LOG!B:B,"MID",MATCH_LOG!G:G,"승")/COUNTIFS(MATCH_LOG!A:A,A31,MATCH_LOG!B:B,"MID"),0) -> 0 | J31: =IFERROR(COUNTIFS(MATCH_LOG!A:A,A31,MATCH_LOG!B:B,"ADC",MATCH_LOG!G:G,"승")/COUNTIFS(MATCH_LOG!A:A,A31,MATCH_LOG!B:B,"ADC"),0) -> 0.61111111 | K31: =IFERROR(COUNTIFS(MATCH_LOG!A:A,A31,MATCH_LOG!B:B,"SUP",MATCH_LOG!G:G,"승")/COUNTIFS(MATCH_LOG!A:A,A31,MATCH_LOG!B:B,"SUP"),0) -> 0.5 | L31: 스몰더 | M31: 5 | N31: 이즈리얼 | O31: 5 | P31: 애쉬 | Q31: 3 | R31: =SUMIFS(MATCH_LOG!D:D,MATCH_LOG!A:A,A31) -> 110 | S31: =SUMIFS(MATCH_LOG!E:E,MATCH_LOG!A:A,A31) -> 131 | T31: =SUMIFS(MATCH_LOG!F:F,MATCH_LOG!A:A,A31) -> 280
A32: 시온 | B32: =COUNTIF(MATCH_LOG!A:A,A32) -> 27 | C32: =COUNTIFS(MATCH_LOG!A:A,A32,MATCH_LOG!G:G,"승") -> 9 | D32: =COUNTIFS(MATCH_LOG!A:A,A32,MATCH_LOG!G:G,"패") -> 18 | E32: =IF(B32=0,0,C32/B32) -> 0.33333333 | F32: =IFERROR((SUMIFS(MATCH_LOG!D:D,MATCH_LOG!A:A,A32)+SUMIFS(MATCH_LOG!F:F,MATCH_LOG!A:A,A32))/SUMIFS(MATCH_LOG!E:E,MATCH_LOG!A:A,A32),0) -> 2.1321839 | G32: =IFERROR(COUNTIFS(MATCH_LOG!A:A,A32,MATCH_LOG!B:B,"TOP",MATCH_LOG!G:G,"승")/COUNTIFS(MATCH_LOG!A:A,A32,MATCH_LOG!B:B,"TOP"),0) -> 0 | H32: =IFERROR(COUNTIFS(MATCH_LOG!A:A,A32,MATCH_LOG!B:B,"JG",MATCH_LOG!G:G,"승")/COUNTIFS(MATCH_LOG!A:A,A32,MATCH_LOG!B:B,"JG"),0) -> 0 | I32: =IFERROR(COUNTIFS(MATCH_LOG!A:A,A32,MATCH_LOG!B:B,"MID",MATCH_LOG!G:G,"승")/COUNTIFS(MATCH_LOG!A:A,A32,MATCH_LOG!B:B,"MID"),0) -> 0 | J32: =IFERROR(COUNTIFS(MATCH_LOG!A:A,A32,MATCH_LOG!B:B,"ADC",MATCH_LOG!G:G,"승")/COUNTIFS(MATCH_LOG!A:A,A32,MATCH_LOG!B:B,"ADC"),0) -> 0.33333333 | K32: =IFERROR(COUNTIFS(MATCH_LOG!A:A,A32,MATCH_LOG!B:B,"SUP",MATCH_LOG!G:G,"승")/COUNTIFS(MATCH_LOG!A:A,A32,MATCH_LOG!B:B,"SUP"),0) -> 0 | L32: 루시안 | M32: 5 | N32: 카이사 | O32: 3 | P32: 이즈리얼 | Q32: 3 | R32: =SUMIFS(MATCH_LOG!D:D,MATCH_LOG!A:A,A32) -> 180 | S32: =SUMIFS(MATCH_LOG!E:E,MATCH_LOG!A:A,A32) -> 174 | T32: =SUMIFS(MATCH_LOG!F:F,MATCH_LOG!A:A,A32) -> 191
A33: 토니 | B33: =COUNTIF(MATCH_LOG!A:A,A33) -> 13 | C33: =COUNTIFS(MATCH_LOG!A:A,A33,MATCH_LOG!G:G,"승") -> 5 | D33: =COUNTIFS(MATCH_LOG!A:A,A33,MATCH_LOG!G:G,"패") -> 8 | E33: =IF(B33=0,0,C33/B33) -> 0.38461538 | F33: =IFERROR((SUMIFS(MATCH_LOG!D:D,MATCH_LOG!A:A,A33)+SUMIFS(MATCH_LOG!F:F,MATCH_LOG!A:A,A33))/SUMIFS(MATCH_LOG!E:E,MATCH_LOG!A:A,A33),0) -> 2.1304348 | G33: =IFERROR(COUNTIFS(MATCH_LOG!A:A,A33,MATCH_LOG!B:B,"TOP",MATCH_LOG!G:G,"승")/COUNTIFS(MATCH_LOG!A:A,A33,MATCH_LOG!B:B,"TOP"),0) -> 0 | H33: =IFERROR(COUNTIFS(MATCH_LOG!A:A,A33,MATCH_LOG!B:B,"JG",MATCH_LOG!G:G,"승")/COUNTIFS(MATCH_LOG!A:A,A33,MATCH_LOG!B:B,"JG"),0) -> 0 | I33: =IFERROR(COUNTIFS(MATCH_LOG!A:A,A33,MATCH_LOG!B:B,"MID",MATCH_LOG!G:G,"승")/COUNTIFS(MATCH_LOG!A:A,A33,MATCH_LOG!B:B,"MID"),0) -> 0 | J33: =IFERROR(COUNTIFS(MATCH_LOG!A:A,A33,MATCH_LOG!B:B,"ADC",MATCH_LOG!G:G,"승")/COUNTIFS(MATCH_LOG!A:A,A33,MATCH_LOG!B:B,"ADC"),0) -> 0 | K33: =IFERROR(COUNTIFS(MATCH_LOG!A:A,A33,MATCH_LOG!B:B,"SUP",MATCH_LOG!G:G,"승")/COUNTIFS(MATCH_LOG!A:A,A33,MATCH_LOG!B:B,"SUP"),0) -> 0.38461538 | L33: 니코 | M33: 5 | N33: 룰루 | O33: 3 | P33: 쓰레쉬 | Q33: 3 | R33: =SUMIFS(MATCH_LOG!D:D,MATCH_LOG!A:A,A33) -> 11 | S33: =SUMIFS(MATCH_LOG!E:E,MATCH_LOG!A:A,A33) -> 69 | T33: =SUMIFS(MATCH_LOG!F:F,MATCH_LOG!A:A,A33) -> 136
A34: 민종 | B34: =COUNTIF(MATCH_LOG!A:A,A34) -> 2 | C34: =COUNTIFS(MATCH_LOG!A:A,A34,MATCH_LOG!G:G,"승") -> 1 | D34: =COUNTIFS(MATCH_LOG!A:A,A34,MATCH_LOG!G:G,"패") -> 1 | E34: =IF(B34=0,0,C34/B34) -> 0.5 | F34: =IFERROR((SUMIFS(MATCH_LOG!D:D,MATCH_LOG!A:A,A34)+SUMIFS(MATCH_LOG!F:F,MATCH_LOG!A:A,A34))/SUMIFS(MATCH_LOG!E:E,MATCH_LOG!A:A,A34),0) -> 1.8 | G34: =IFERROR(COUNTIFS(MATCH_LOG!A:A,A34,MATCH_LOG!B:B,"TOP",MATCH_LOG!G:G,"승")/COUNTIFS(MATCH_LOG!A:A,A34,MATCH_LOG!B:B,"TOP"),0) -> 0 | H34: =IFERROR(COUNTIFS(MATCH_LOG!A:A,A34,MATCH_LOG!B:B,"JG",MATCH_LOG!G:G,"승")/COUNTIFS(MATCH_LOG!A:A,A34,MATCH_LOG!B:B,"JG"),0) -> 0.5 | I34: =IFERROR(COUNTIFS(MATCH_LOG!A:A,A34,MATCH_LOG!B:B,"MID",MATCH_LOG!G:G,"승")/COUNTIFS(MATCH_LOG!A:A,A34,MATCH_LOG!B:B,"MID"),0) -> 0 | J34: =IFERROR(COUNTIFS(MATCH_LOG!A:A,A34,MATCH_LOG!B:B,"ADC",MATCH_LOG!G:G,"승")/COUNTIFS(MATCH_LOG!A:A,A34,MATCH_LOG!B:B,"ADC"),0) -> 0 | K34: =IFERROR(COUNTIFS(MATCH_LOG!A:A,A34,MATCH_LOG!B:B,"SUP",MATCH_LOG!G:G,"승")/COUNTIFS(MATCH_LOG!A:A,A34,MATCH_LOG!B:B,"SUP"),0) -> 0 | L34: 사일러스 | M34: 1 | N34: 녹턴 | O34: 1 | R34: =SUMIFS(MATCH_LOG!D:D,MATCH_LOG!A:A,A34) -> 5 | S34: =SUMIFS(MATCH_LOG!E:E,MATCH_LOG!A:A,A34) -> 15 | T34: =SUMIFS(MATCH_LOG!F:F,MATCH_LOG!A:A,A34) -> 22
A35: 시현 | B35: =COUNTIF(MATCH_LOG!A:A,A35) -> 2 | C35: =COUNTIFS(MATCH_LOG!A:A,A35,MATCH_LOG!G:G,"승") -> 2 | D35: =COUNTIFS(MATCH_LOG!A:A,A35,MATCH_LOG!G:G,"패") -> 0 | E35: =IF(B35=0,0,C35/B35) -> 1 | F35: =IFERROR((SUMIFS(MATCH_LOG!D:D,MATCH_LOG!A:A,A35)+SUMIFS(MATCH_LOG!F:F,MATCH_LOG!A:A,A35))/SUMIFS(MATCH_LOG!E:E,MATCH_LOG!A:A,A35),0) -> 3.5714286 | G35: =IFERROR(COUNTIFS(MATCH_LOG!A:A,A35,MATCH_LOG!B:B,"TOP",MATCH_LOG!G:G,"승")/COUNTIFS(MATCH_LOG!A:A,A35,MATCH_LOG!B:B,"TOP"),0) -> 0 | H35: =IFERROR(COUNTIFS(MATCH_LOG!A:A,A35,MATCH_LOG!B:B,"JG",MATCH_LOG!G:G,"승")/COUNTIFS(MATCH_LOG!A:A,A35,MATCH_LOG!B:B,"JG"),0) -> 0 | I35: =IFERROR(COUNTIFS(MATCH_LOG!A:A,A35,MATCH_LOG!B:B,"MID",MATCH_LOG!G:G,"승")/COUNTIFS(MATCH_LOG!A:A,A35,MATCH_LOG!B:B,"MID"),0) -> 1 | J35: =IFERROR(COUNTIFS(MATCH_LOG!A:A,A35,MATCH_LOG!B:B,"ADC",MATCH_LOG!G:G,"승")/COUNTIFS(MATCH_LOG!A:A,A35,MATCH_LOG!B:B,"ADC"),0) -> 0 | K35: =IFERROR(COUNTIFS(MATCH_LOG!A:A,A35,MATCH_LOG!B:B,"SUP",MATCH_LOG!G:G,"승")/COUNTIFS(MATCH_LOG!A:A,A35,MATCH_LOG!B:B,"SUP"),0) -> 0 | L35: 제라스 | M35: 1 | N35: 빅토르 | O35: 1 | R35: =SUMIFS(MATCH_LOG!D:D,MATCH_LOG!A:A,A35) -> 11 | S35: =SUMIFS(MATCH_LOG!E:E,MATCH_LOG!A:A,A35) -> 7 | T35: =SUMIFS(MATCH_LOG!F:F,MATCH_LOG!A:A,A35) -> 14
A36: 승현 | B36: =COUNTIF(MATCH_LOG!A:A,A36) -> 14 | C36: =COUNTIFS(MATCH_LOG!A:A,A36,MATCH_LOG!G:G,"승") -> 6 | D36: =COUNTIFS(MATCH_LOG!A:A,A36,MATCH_LOG!G:G,"패") -> 8 | E36: =IF(B36=0,0,C36/B36) -> 0.42857143 | F36: =IFERROR((SUMIFS(MATCH_LOG!D:D,MATCH_LOG!A:A,A36)+SUMIFS(MATCH_LOG!F:F,MATCH_LOG!A:A,A36))/SUMIFS(MATCH_LOG!E:E,MATCH_LOG!A:A,A36),0) -> 2.3235294 | G36: =IFERROR(COUNTIFS(MATCH_LOG!A:A,A36,MATCH_LOG!B:B,"TOP",MATCH_LOG!G:G,"승")/COUNTIFS(MATCH_LOG!A:A,A36,MATCH_LOG!B:B,"TOP"),0) -> 0.4 | H36: =IFERROR(COUNTIFS(MATCH_LOG!A:A,A36,MATCH_LOG!B:B,"JG",MATCH_LOG!G:G,"승")/COUNTIFS(MATCH_LOG!A:A,A36,MATCH_LOG!B:B,"JG"),0) -> 0.5 | I36: =IFERROR(COUNTIFS(MATCH_LOG!A:A,A36,MATCH_LOG!B:B,"MID",MATCH_LOG!G:G,"승")/COUNTIFS(MATCH_LOG!A:A,A36,MATCH_LOG!B:B,"MID"),0) -> 0 | J36: =IFERROR(COUNTIFS(MATCH_LOG!A:A,A36,MATCH_LOG!B:B,"ADC",MATCH_LOG!G:G,"승")/COUNTIFS(MATCH_LOG!A:A,A36,MATCH_LOG!B:B,"ADC"),0) -> 0 | K36: =IFERROR(COUNTIFS(MATCH_LOG!A:A,A36,MATCH_LOG!B:B,"SUP",MATCH_LOG!G:G,"승")/COUNTIFS(MATCH_LOG!A:A,A36,MATCH_LOG!B:B,"SUP"),0) -> 0.4 | L36: 모데카이저 | M36: 3 | N36: 밀리오 | O36: 2 | P36: 리신 | Q36: 2 | R36: =SUMIFS(MATCH_LOG!D:D,MATCH_LOG!A:A,A36) -> 41 | S36: =SUMIFS(MATCH_LOG!E:E,MATCH_LOG!A:A,A36) -> 68 | T36: =SUMIFS(MATCH_LOG!F:F,MATCH_LOG!A:A,A36) -> 117
A37: 매드 | B37: =COUNTIF(MATCH_LOG!A:A,A37) -> 2 | C37: =COUNTIFS(MATCH_LOG!A:A,A37,MATCH_LOG!G:G,"승") -> 1 | D37: =COUNTIFS(MATCH_LOG!A:A,A37,MATCH_LOG!G:G,"패") -> 1 | E37: =IF(B37=0,0,C37/B37) -> 0.5 | F37: =IFERROR((SUMIFS(MATCH_LOG!D:D,MATCH_LOG!A:A,A37)+SUMIFS(MATCH_LOG!F:F,MATCH_LOG!A:A,A37))/SUMIFS(MATCH_LOG!E:E,MATCH_LOG!A:A,A37),0) -> 3.25 | G37: =IFERROR(COUNTIFS(MATCH_LOG!A:A,A37,MATCH_LOG!B:B,"TOP",MATCH_LOG!G:G,"승")/COUNTIFS(MATCH_LOG!A:A,A37,MATCH_LOG!B:B,"TOP"),0) -> 0 | H37: =IFERROR(COUNTIFS(MATCH_LOG!A:A,A37,MATCH_LOG!B:B,"JG",MATCH_LOG!G:G,"승")/COUNTIFS(MATCH_LOG!A:A,A37,MATCH_LOG!B:B,"JG"),0) -> 0 | I37: =IFERROR(COUNTIFS(MATCH_LOG!A:A,A37,MATCH_LOG!B:B,"MID",MATCH_LOG!G:G,"승")/COUNTIFS(MATCH_LOG!A:A,A37,MATCH_LOG!B:B,"MID"),0) -> 0 | J37: =IFERROR(COUNTIFS(MATCH_LOG!A:A,A37,MATCH_LOG!B:B,"ADC",MATCH_LOG!G:G,"승")/COUNTIFS(MATCH_LOG!A:A,A37,MATCH_LOG!B:B,"ADC"),0) -> 0.5 | K37: =IFERROR(COUNTIFS(MATCH_LOG!A:A,A37,MATCH_LOG!B:B,"SUP",MATCH_LOG!G:G,"승")/COUNTIFS(MATCH_LOG!A:A,A37,MATCH_LOG!B:B,"SUP"),0) -> 0 | L37: 징크스 | M37: 1 | N37: 케이틀린 | O37: 1 | R37: =SUMIFS(MATCH_LOG!D:D,MATCH_LOG!A:A,A37) -> 14 | S37: =SUMIFS(MATCH_LOG!E:E,MATCH_LOG!A:A,A37) -> 8 | T37: =SUMIFS(MATCH_LOG!F:F,MATCH_LOG!A:A,A37) -> 12
A38: 잡채밥 | B38: =COUNTIF(MATCH_LOG!A:A,A38) -> 5 | C38: =COUNTIFS(MATCH_LOG!A:A,A38,MATCH_LOG!G:G,"승") -> 5 | D38: =COUNTIFS(MATCH_LOG!A:A,A38,MATCH_LOG!G:G,"패") -> 0 | E38: =IF(B38=0,0,C38/B38) -> 1 | F38: =IFERROR((SUMIFS(MATCH_LOG!D:D,MATCH_LOG!A:A,A38)+SUMIFS(MATCH_LOG!F:F,MATCH_LOG!A:A,A38))/SUMIFS(MATCH_LOG!E:E,MATCH_LOG!A:A,A38),0) -> 3.05 | G38: =IFERROR(COUNTIFS(MATCH_LOG!A:A,A38,MATCH_LOG!B:B,"TOP",MATCH_LOG!G:G,"승")/COUNTIFS(MATCH_LOG!A:A,A38,MATCH_LOG!B:B,"TOP"),0) -> 0 | H38: =IFERROR(COUNTIFS(MATCH_LOG!A:A,A38,MATCH_LOG!B:B,"JG",MATCH_LOG!G:G,"승")/COUNTIFS(MATCH_LOG!A:A,A38,MATCH_LOG!B:B,"JG"),0) -> 0 | I38: =IFERROR(COUNTIFS(MATCH_LOG!A:A,A38,MATCH_LOG!B:B,"MID",MATCH_LOG!G:G,"승")/COUNTIFS(MATCH_LOG!A:A,A38,MATCH_LOG!B:B,"MID"),0) -> 0 | J38: =IFERROR(COUNTIFS(MATCH_LOG!A:A,A38,MATCH_LOG!B:B,"ADC",MATCH_LOG!G:G,"승")/COUNTIFS(MATCH_LOG!A:A,A38,MATCH_LOG!B:B,"ADC"),0) -> 0 | K38: =IFERROR(COUNTIFS(MATCH_LOG!A:A,A38,MATCH_LOG!B:B,"SUP",MATCH_LOG!G:G,"승")/COUNTIFS(MATCH_LOG!A:A,A38,MATCH_LOG!B:B,"SUP"),0) -> 1 | L38: 카르마 | M38: 3 | N38: 밀리오 | O38: 1 | P38: 세라핀 | Q38: 1 | R38: =SUMIFS(MATCH_LOG!D:D,MATCH_LOG!A:A,A38) -> 6 | S38: =SUMIFS(MATCH_LOG!E:E,MATCH_LOG!A:A,A38) -> 20 | T38: =SUMIFS(MATCH_LOG!F:F,MATCH_LOG!A:A,A38) -> 55
A39: 한울 | B39: =COUNTIF(MATCH_LOG!A:A,A39) -> 4 | C39: =COUNTIFS(MATCH_LOG!A:A,A39,MATCH_LOG!G:G,"승") -> 3 | D39: =COUNTIFS(MATCH_LOG!A:A,A39,MATCH_LOG!G:G,"패") -> 1 | E39: =IF(B39=0,0,C39/B39) -> 0.75 | F39: =IFERROR((SUMIFS(MATCH_LOG!D:D,MATCH_LOG!A:A,A39)+SUMIFS(MATCH_LOG!F:F,MATCH_LOG!A:A,A39))/SUMIFS(MATCH_LOG!E:E,MATCH_LOG!A:A,A39),0) -> 1.6 | G39: =IFERROR(COUNTIFS(MATCH_LOG!A:A,A39,MATCH_LOG!B:B,"TOP",MATCH_LOG!G:G,"승")/COUNTIFS(MATCH_LOG!A:A,A39,MATCH_LOG!B:B,"TOP"),0) -> 1 | H39: =IFERROR(COUNTIFS(MATCH_LOG!A:A,A39,MATCH_LOG!B:B,"JG",MATCH_LOG!G:G,"승")/COUNTIFS(MATCH_LOG!A:A,A39,MATCH_LOG!B:B,"JG"),0) -> 0 | I39: =IFERROR(COUNTIFS(MATCH_LOG!A:A,A39,MATCH_LOG!B:B,"MID",MATCH_LOG!G:G,"승")/COUNTIFS(MATCH_LOG!A:A,A39,MATCH_LOG!B:B,"MID"),0) -> 0 | J39: =IFERROR(COUNTIFS(MATCH_LOG!A:A,A39,MATCH_LOG!B:B,"ADC",MATCH_LOG!G:G,"승")/COUNTIFS(MATCH_LOG!A:A,A39,MATCH_LOG!B:B,"ADC"),0) -> 0 | K39: =IFERROR(COUNTIFS(MATCH_LOG!A:A,A39,MATCH_LOG!B:B,"SUP",MATCH_LOG!G:G,"승")/COUNTIFS(MATCH_LOG!A:A,A39,MATCH_LOG!B:B,"SUP"),0) -> 0 | L39: 바루스 | M39: 1 | N39: 말파이트 | O39: 1 | P39: 문도 | Q39: 1 | R39: =SUMIFS(MATCH_LOG!D:D,MATCH_LOG!A:A,A39) -> 12 | S39: =SUMIFS(MATCH_LOG!E:E,MATCH_LOG!A:A,A39) -> 20 | T39: =SUMIFS(MATCH_LOG!F:F,MATCH_LOG!A:A,A39) -> 20
A40: 나경 | B40: =COUNTIF(MATCH_LOG!A:A,A40) -> 5 | C40: =COUNTIFS(MATCH_LOG!A:A,A40,MATCH_LOG!G:G,"승") -> 1 | D40: =COUNTIFS(MATCH_LOG!A:A,A40,MATCH_LOG!G:G,"패") -> 4 | E40: =IF(B40=0,0,C40/B40) -> 0.2 | F40: =IFERROR((SUMIFS(MATCH_LOG!D:D,MATCH_LOG!A:A,A40)+SUMIFS(MATCH_LOG!F:F,MATCH_LOG!A:A,A40))/SUMIFS(MATCH_LOG!E:E,MATCH_LOG!A:A,A40),0) -> 2.4761905 | G40: =IFERROR(COUNTIFS(MATCH_LOG!A:A,A40,MATCH_LOG!B:B,"TOP",MATCH_LOG!G:G,"승")/COUNTIFS(MATCH_LOG!A:A,A40,MATCH_LOG!B:B,"TOP"),0) -> 0 | H40: =IFERROR(COUNTIFS(MATCH_LOG!A:A,A40,MATCH_LOG!B:B,"JG",MATCH_LOG!G:G,"승")/COUNTIFS(MATCH_LOG!A:A,A40,MATCH_LOG!B:B,"JG"),0) -> 0 | I40: =IFERROR(COUNTIFS(MATCH_LOG!A:A,A40,MATCH_LOG!B:B,"MID",MATCH_LOG!G:G,"승")/COUNTIFS(MATCH_LOG!A:A,A40,MATCH_LOG!B:B,"MID"),0) -> 0 | J40: =IFERROR(COUNTIFS(MATCH_LOG!A:A,A40,MATCH_LOG!B:B,"ADC",MATCH_LOG!G:G,"승")/COUNTIFS(MATCH_LOG!A:A,A40,MATCH_LOG!B:B,"ADC"),0) -> 0 | K40: =IFERROR(COUNTIFS(MATCH_LOG!A:A,A40,MATCH_LOG!B:B,"SUP",MATCH_LOG!G:G,"승")/COUNTIFS(MATCH_LOG!A:A,A40,MATCH_LOG!B:B,"SUP"),0) -> 0.2 | L40: 유미 | M40: 2 | N40: 룰루 | O40: 2 | P40: 세라핀 | Q40: 1 | R40: =SUMIFS(MATCH_LOG!D:D,MATCH_LOG!A:A,A40) -> 3 | S40: =SUMIFS(MATCH_LOG!E:E,MATCH_LOG!A:A,A40) -> 21 | T40: =SUMIFS(MATCH_LOG!F:F,MATCH_LOG!A:A,A40) -> 49
A41: 민규 | B41: =COUNTIF(MATCH_LOG!A:A,A41) -> 2 | C41: =COUNTIFS(MATCH_LOG!A:A,A41,MATCH_LOG!G:G,"승") -> 2 | D41: =COUNTIFS(MATCH_LOG!A:A,A41,MATCH_LOG!G:G,"패") -> 0 | E41: =IF(B41=0,0,C41/B41) -> 1 | F41: =IFERROR((SUMIFS(MATCH_LOG!D:D,MATCH_LOG!A:A,A41)+SUMIFS(MATCH_LOG!F:F,MATCH_LOG!A:A,A41))/SUMIFS(MATCH_LOG!E:E,MATCH_LOG!A:A,A41),0) -> 4.5 | G41: =IFERROR(COUNTIFS(MATCH_LOG!A:A,A41,MATCH_LOG!B:B,"TOP",MATCH_LOG!G:G,"승")/COUNTIFS(MATCH_LOG!A:A,A41,MATCH_LOG!B:B,"TOP"),0) -> 0 | H41: =IFERROR(COUNTIFS(MATCH_LOG!A:A,A41,MATCH_LOG!B:B,"JG",MATCH_LOG!G:G,"승")/COUNTIFS(MATCH_LOG!A:A,A41,MATCH_LOG!B:B,"JG"),0) -> 0 | I41: =IFERROR(COUNTIFS(MATCH_LOG!A:A,A41,MATCH_LOG!B:B,"MID",MATCH_LOG!G:G,"승")/COUNTIFS(MATCH_LOG!A:A,A41,MATCH_LOG!B:B,"MID"),0) -> 1 | J41: =IFERROR(COUNTIFS(MATCH_LOG!A:A,A41,MATCH_LOG!B:B,"ADC",MATCH_LOG!G:G,"승")/COUNTIFS(MATCH_LOG!A:A,A41,MATCH_LOG!B:B,"ADC"),0) -> 0 | K41: =IFERROR(COUNTIFS(MATCH_LOG!A:A,A41,MATCH_LOG!B:B,"SUP",MATCH_LOG!G:G,"승")/COUNTIFS(MATCH_LOG!A:A,A41,MATCH_LOG!B:B,"SUP"),0) -> 0 | L41: 요네 | M41: 1 | N41: 갈리오 | O41: 1 | R41: =SUMIFS(MATCH_LOG!D:D,MATCH_LOG!A:A,A41) -> 6 | S41: =SUMIFS(MATCH_LOG!E:E,MATCH_LOG!A:A,A41) -> 6 | T41: =SUMIFS(MATCH_LOG!F:F,MATCH_LOG!A:A,A41) -> 21
A42: 에어그로브 | B42: =COUNTIF(MATCH_LOG!A:A,A42) -> 3 | C42: =COUNTIFS(MATCH_LOG!A:A,A42,MATCH_LOG!G:G,"승") -> 3 | D42: =COUNTIFS(MATCH_LOG!A:A,A42,MATCH_LOG!G:G,"패") -> 0 | E42: =IF(B42=0,0,C42/B42) -> 1 | F42: =IFERROR((SUMIFS(MATCH_LOG!D:D,MATCH_LOG!A:A,A42)+SUMIFS(MATCH_LOG!F:F,MATCH_LOG!A:A,A42))/SUMIFS(MATCH_LOG!E:E,MATCH_LOG!A:A,A42),0) -> 2.1428571 | G42: =IFERROR(COUNTIFS(MATCH_LOG!A:A,A42,MATCH_LOG!B:B,"TOP",MATCH_LOG!G:G,"승")/COUNTIFS(MATCH_LOG!A:A,A42,MATCH_LOG!B:B,"TOP"),0) -> 0 | H42: =IFERROR(COUNTIFS(MATCH_LOG!A:A,A42,MATCH_LOG!B:B,"JG",MATCH_LOG!G:G,"승")/COUNTIFS(MATCH_LOG!A:A,A42,MATCH_LOG!B:B,"JG"),0) -> 0 | I42: =IFERROR(COUNTIFS(MATCH_LOG!A:A,A42,MATCH_LOG!B:B,"MID",MATCH_LOG!G:G,"승")/COUNTIFS(MATCH_LOG!A:A,A42,MATCH_LOG!B:B,"MID"),0) -> 0 | J42: =IFERROR(COUNTIFS(MATCH_LOG!A:A,A42,MATCH_LOG!B:B,"ADC",MATCH_LOG!G:G,"승")/COUNTIFS(MATCH_LOG!A:A,A42,MATCH_LOG!B:B,"ADC"),0) -> 0 | K42: =IFERROR(COUNTIFS(MATCH_LOG!A:A,A42,MATCH_LOG!B:B,"SUP",MATCH_LOG!G:G,"승")/COUNTIFS(MATCH_LOG!A:A,A42,MATCH_LOG!B:B,"SUP"),0) -> 1 | L42: 나미 | M42: 1 | N42: 판테온 | O42: 1 | P42: 브라움 | Q42: 1 | R42: =SUMIFS(MATCH_LOG!D:D,MATCH_LOG!A:A,A42) -> 5 | S42: =SUMIFS(MATCH_LOG!E:E,MATCH_LOG!A:A,A42) -> 21 | T42: =SUMIFS(MATCH_LOG!F:F,MATCH_LOG!A:A,A42) -> 40
A43: 모아 | B43: =COUNTIF(MATCH_LOG!A:A,A43) -> 2 | C43: =COUNTIFS(MATCH_LOG!A:A,A43,MATCH_LOG!G:G,"승") -> 1 | D43: =COUNTIFS(MATCH_LOG!A:A,A43,MATCH_LOG!G:G,"패") -> 1 | E43: =IF(B43=0,0,C43/B43) -> 0.5 | F43: =IFERROR((SUMIFS(MATCH_LOG!D:D,MATCH_LOG!A:A,A43)+SUMIFS(MATCH_LOG!F:F,MATCH_LOG!A:A,A43))/SUMIFS(MATCH_LOG!E:E,MATCH_LOG!A:A,A43),0) -> 3.5384615 | G43: =IFERROR(COUNTIFS(MATCH_LOG!A:A,A43,MATCH_LOG!B:B,"TOP",MATCH_LOG!G:G,"승")/COUNTIFS(MATCH_LOG!A:A,A43,MATCH_LOG!B:B,"TOP"),0) -> 0 | H43: =IFERROR(COUNTIFS(MATCH_LOG!A:A,A43,MATCH_LOG!B:B,"JG",MATCH_LOG!G:G,"승")/COUNTIFS(MATCH_LOG!A:A,A43,MATCH_LOG!B:B,"JG"),0) -> 0 | I43: =IFERROR(COUNTIFS(MATCH_LOG!A:A,A43,MATCH_LOG!B:B,"MID",MATCH_LOG!G:G,"승")/COUNTIFS(MATCH_LOG!A:A,A43,MATCH_LOG!B:B,"MID"),0) -> 0 | J43: =IFERROR(COUNTIFS(MATCH_LOG!A:A,A43,MATCH_LOG!B:B,"ADC",MATCH_LOG!G:G,"승")/COUNTIFS(MATCH_LOG!A:A,A43,MATCH_LOG!B:B,"ADC"),0) -> 0 | K43: =IFERROR(COUNTIFS(MATCH_LOG!A:A,A43,MATCH_LOG!B:B,"SUP",MATCH_LOG!G:G,"승")/COUNTIFS(MATCH_LOG!A:A,A43,MATCH_LOG!B:B,"SUP"),0) -> 0.5 | L43: 니코 | M43: 1 | N43: 알리스타 | O43: 1 | R43: =SUMIFS(MATCH_LOG!D:D,MATCH_LOG!A:A,A43) -> 10 | S43: =SUMIFS(MATCH_LOG!E:E,MATCH_LOG!A:A,A43) -> 13 | T43: =SUMIFS(MATCH_LOG!F:F,MATCH_LOG!A:A,A43) -> 36
A44: 토드 | B44: =COUNTIF(MATCH_LOG!A:A,A44) -> 3 | C44: =COUNTIFS(MATCH_LOG!A:A,A44,MATCH_LOG!G:G,"승") -> 1 | D44: =COUNTIFS(MATCH_LOG!A:A,A44,MATCH_LOG!G:G,"패") -> 2 | E44: =IF(B44=0,0,C44/B44) -> 0.33333333 | F44: =IFERROR((SUMIFS(MATCH_LOG!D:D,MATCH_LOG!A:A,A44)+SUMIFS(MATCH_LOG!F:F,MATCH_LOG!A:A,A44))/SUMIFS(MATCH_LOG!E:E,MATCH_LOG!A:A,A44),0) -> 2.5185185 | G44: =IFERROR(COUNTIFS(MATCH_LOG!A:A,A44,MATCH_LOG!B:B,"TOP",MATCH_LOG!G:G,"승")/COUNTIFS(MATCH_LOG!A:A,A44,MATCH_LOG!B:B,"TOP"),0) -> 0 | H44: =IFERROR(COUNTIFS(MATCH_LOG!A:A,A44,MATCH_LOG!B:B,"JG",MATCH_LOG!G:G,"승")/COUNTIFS(MATCH_LOG!A:A,A44,MATCH_LOG!B:B,"JG"),0) -> 0 | I44: =IFERROR(COUNTIFS(MATCH_LOG!A:A,A44,MATCH_LOG!B:B,"MID",MATCH_LOG!G:G,"승")/COUNTIFS(MATCH_LOG!A:A,A44,MATCH_LOG!B:B,"MID"),0) -> 0 | J44: =IFERROR(COUNTIFS(MATCH_LOG!A:A,A44,MATCH_LOG!B:B,"ADC",MATCH_LOG!G:G,"승")/COUNTIFS(MATCH_LOG!A:A,A44,MATCH_LOG!B:B,"ADC"),0) -> 0 | K44: =IFERROR(COUNTIFS(MATCH_LOG!A:A,A44,MATCH_LOG!B:B,"SUP",MATCH_LOG!G:G,"승")/COUNTIFS(MATCH_LOG!A:A,A44,MATCH_LOG!B:B,"SUP"),0) -> 0.33333333 | L44: 쓰레쉬 | M44: 2 | N44: 파이크 | O44: 1 | R44: =SUMIFS(MATCH_LOG!D:D,MATCH_LOG!A:A,A44) -> 12 | S44: =SUMIFS(MATCH_LOG!E:E,MATCH_LOG!A:A,A44) -> 27 | T44: =SUMIFS(MATCH_LOG!F:F,MATCH_LOG!A:A,A44) -> 56
...

Sheet MATCH_LOG
A1: 닉네임 | B1: 라인 | C1: 챔피언(안 써도 됨) | D1: K | E1: D | F1: A | G1: 결과
B2: TOP | G2: 승
B3: JG | G3: 승
B4: MID | G4: 승
B5: ADC | G5: 승
B6: SUP | G6: 승
B7: TOP | G7: 패
B8: JG | G8: 패
B9: MID | G9: 패
B10: ADC | G10: 패
B11: SUP | G11: 패
A17: 닉네임 | B17: 라인 | C17: 챔피언(안 써도 됨) | D17: K | E17: D | F17: A | G17: 결과
A18: 승현 | B18: TOP | C18: 모데카이저 | D18: 7 | E18: 2 | F18: 2 | G18: 승
A19: 희영 | B19: JG | C19: 바이 | D19: 14 | E19: 0 | F19: 8 | G19: 승
A20: 도현 | B20: MID | C20: 암베사 | D20: 3 | E20: 2 | F20: 10 | G20: 승
A21: 시온 | B21: ADC | C21: 진 | D21: 20 | E21: 4 | F21: 9 | G21: 승
A22: 상기 | B22: SUP | C22: 스카너 | D22: 6 | E22: 6 | F22: 24 | G22: 승
A23: 망수 | B23: TOP | C23: 올라프 | D23: 1 | E23: 10 | F23: 0 | G23: 패
A24: 수호 | B24: JG | C24: 비에고 | D24: 8 | E24: 8 | F24: 2 | G24: 패
A25: 세준 | B25: MID | C25: 아리 | D25: 2 | E25: 10 | F25: 5 | G25: 패
A26: 유현 | B26: ADC | C26: 애쉬 | D26: 1 | E26: 12 | F26: 3 | G26: 패
A27: 나경 | B27: SUP | C27: 세라핀 | D27: 2 | E27: 10 | F27: 7 | G27: 패
A29: 닉네임 | B29: 라인 | C29: 챔피언(안 써도 됨) | D29: K | E29: D | F29: A | G29: 결과
A30: 망수 | B30: TOP | C30: 케일 | D30: 5 | E30: 8 | F30: 3 | G30: 승
A31: 수호 | B31: JG | C31: 오공 | D31: 11 | E31: 2 | F31: 10 | G31: 승
A32: 세준 | B32: MID | C32: 갈리오 | D32: 4 | E32: 4 | F32: 8 | G32: 승
A33: 유현 | B33: ADC | C33: 스몰더 | D33: 6 | E33: 0 | F33: 10 | G33: 승
A34: 나경 | B34: SUP | C34: 유미 | D34: 0 | E34: 0 | F34: 17 | G34: 승
A35: 상기 | B35: TOP | C35: 크산테 | D35: 3 | E35: 8 | F35: 4 | G35: 패
A36: 희영 | B36: JG | C36: 세주아니 | D36: 6 | E36: 4 | F36: 3 | G36: 패
A37: 도현 | B37: MID | C37: 야스오 | D37: 5 | E37: 3 | F37: 1 | G37: 패
A38: 시온 | B38: ADC | C38: 카이사 | D38: 0 | E38: 5 | F38: 1 | G38: 패
A39: 승현 | B39: SUP | C39: 노틸러스 | D39: 0 | E39: 6 | F39: 0 | G39: 패
A41: 닉네임 | B41: 라인 | C41: 챔피언(안 써도 됨) | D41: K | E41: D | F41: A | G41: 결과
A42: 상기 | B42: TOP | C42: 오른 | D42: 8 | E42: 2 | F42: 2 | G42: 승
A43: 희영 | B43: JG | C43: 탈론 | D43: 3 | E43: 2 | F43: 7 | G43: 승
A44: 도현 | B44: MID | C44: 오로라 | D44: 8 | E44: 1 | F44: 0 | G44: 승
A45: 시온 | B45: ADC | C45: 루시안 | D45: 7 | E45: 0 | F45: 1 | G45: 승
A46: 승현 | B46: SUP | C46: 밀리오 | D46: 0 | E46: 1 | F46: 8 | G46: 승
A47: 망수 | B47: TOP | C47: 아트록스 | D47: 1 | E47: 9 | F47: 2 | G47: 패
...
